Workbook

Sheet ⓪作業手順メモ
A1: １．最新名簿で、「①会員名簿マスタ」シートの内容を更新する。
A3: 会員名簿の中から、「㈲峯田工業」など祭礼寄付をいただいていない会員の行を除去する。
A6: ３．「②差し込み印刷用４段」シートにマッピングする。
A8: 「①会員名簿マスタ」シートの会員数を確認し、その値を４で割った値（割り切れない場合、＋１）の
A9: 行数の差し込み印刷用４段シートを作成する。
A10: 寄付が期待できる会員数が、１７７の場合、１７７÷４＝４４．２５なので、４５行１列のシートにする
A11: 左上から１区１班、１区２班・・・と割り当て４４世帯まできたら、次の列に・・・
A12: １７７世帯を埋めていく

Sheet ①会員名簿マスタ
A1: 駒寄町内会 会員名簿 (2025年6月29日現在)
A2: 通番 | B2: 区 | C2: 班 | D2: No. | E2: 評議員 | F2: 氏名 ／ 屋号 | G2: 住所番地 | H2: 電 話 | I2: 備 考
A3: =ROW()-2 -> 1 | B3: 1 | C3: 1 | D3: =IF(AND(B2=B3,C2=C3),D2+1,1) -> 1 | F3: 中村芳朗 | G3: 6－1 | H3: 861－2770
A4: =ROW()-2 -> 2 | B4: 1 | C4: 1 | D4: =IF(AND(B3=B4,C3=C4),D3+1,1) -> 2 | F4: 中村治子 | G4: 6－1 | H4: 861－2446
A5: =ROW()-2 -> 3 | B5: 1 | C5: 1 | D5: =IF(AND(B4=B5,C4=C5),D4+1,1) -> 3 | F5: 松川正士 | G5: 6－1 | H5: 861－2384
A6: =ROW()-2 -> 4 | B6: 1 | C6: 1 | D6: =IF(AND(B5=B6,C5=C6),D5+1,1) -> 4 | F6: 和田薪 | G6: 6－1 | H6: 861－2481 | I6: セラヴィ
A7: =ROW()-2 -> 5 | B7: 1 | C7: 1 | D7: =IF(AND(B6=B7,C6=C7),D6+1,1) -> 5 | F7: 平井進 | G7: 6－1 | H7: 861－3291
A8: =ROW()-2 -> 6 | B8: 1 | C8: 1 | D8: =IF(AND(B7=B8,C7=C8),D7+1,1) -> 6 | F8: 長谷川聡 | G8: 6－1 | I8: H29.4～
A9: =ROW()-2 -> 7 | B9: 1 | C9: 1 | D9: =IF(AND(B8=B9,C8=C9),D8+1,1) -> 7 | F9: 粟飯原功 | G9: 6－2 | H9: 861－4015
A10: =ROW()-2 -> 8 | B10: 1 | C10: 1 | D10: =IF(AND(B9=B10,C9=C10),D9+1,1) -> 8 | F10: 高橋正 | G10: 6－2 | H10: 861－0178 | I10: R3.評議員は「しのぶ」さん
A11: =ROW()-2 -> 9 | B11: 1 | C11: 1 | D11: =IF(AND(B10=B11,C10=C11),D10+1,1) -> 9 | E11: ● | F11: 林信行 | G11: 6－2 | H11: 090-3916-4588 | I11: H29.4～ 046-854-9786
A12: =ROW()-2 -> 10 | B12: 1 | C12: 2 | D12: =IF(AND(B11=B12,C11=C12),D11+1,1) -> 1 | F12: 紺野建設 | G12: 6－69 | H12: 861－3180
A13: =ROW()-2 -> 11 | B13: 1 | C13: 2 | D13: =IF(AND(B12=B13,C12=C13),D12+1,1) -> 2 | F13: 遠山悦子 | G13: 6－68 | H13: 861－3815 | I13: R5.美代子さん逝去
A14: =ROW()-2 -> 12 | B14: 1 | C14: 2 | D14: =IF(AND(B13=B14,C13=C14),D13+1,1) -> 3 | F14: 高瀬一 | G14: 6－69 | H14: 861－0509
A15: =ROW()-2 -> 13 | B15: 1 | C15: 2 | D15: =IF(AND(B14=B15,C14=C15),D14+1,1) -> 4 | E15: ● | F15: 齋藤勇 | G15: 6－68 | H15: 861－3823
A16: =ROW()-2 -> 14 | B16: 1 | C16: 2 | D16: =IF(AND(B15=B16,C15=C16),D15+1,1) -> 5 | F16: 鍋田益男 | G16: 6－68 | H16: 861－5959
A17: =ROW()-2 -> 15 | B17: 1 | C17: 2 | D17: =IF(AND(B16=B17,C16=C17),D16+1,1) -> 6 | F17: マミークリーニング | G17: 6－68 | H17: 861－1220
A18: =ROW()-2 -> 16 | B18: 1 | C18: 2 | D18: =IF(AND(B17=B18,C17=C18),D17+1,1) -> 7 | F18: 佐藤清 | G18: 6－69 | H18: 861－6235 | I18: H29.4～
A19: =ROW()-2 -> 17 | B19: 1 | C19: 2 | D19: =IF(AND(B18=B19,C18=C19),D18+1,1) -> 8 | F19: 戸村則登 | G19: 6－68-19 | H19: 090-6346-9518 | I19: R7.6月加入、S33.7.29生
A20: =ROW()-2 -> 18 | B20: 1 | C20: 3 | D20: =IF(AND(B18=B20,C18=C20),D18+1,1) -> 1 | E20: ● | F20: 佐久間明 | G20: 6－69 | H20: 861－3753
A21: =ROW()-2 -> 19 | B21: 1 | C21: 3 | D21: =IF(AND(B20=B21,C20=C21),D20+1,1) -> 2 | F21: 鳥居スミヱ | G21: 6－77 | H21: 861－4993 | I21: 評議員は鳥居知加代
A22: =ROW()-2 -> 20 | B22: 1 | C22: 3 | D22: =IF(AND(B21=B22,C21=C22),D21+1,1) -> 3 | F22: 渋江康弘 | G22: 6－77 | H22: 897－7032
A23: =ROW()-2 -> 21 | B23: 1 | C23: 3 | D23: =IF(AND(B22=B23,C22=C23),D22+1,1) -> 4 | F23: 石岡明憲 | G23: 6－77 | H23: 861－0925
A24: =ROW()-2 -> 22 | B24: 1 | C24: 3 | D24: =IF(AND(B23=B24,C23=C24),D23+1,1) -> 5 | F24: 中華料理成都 | G24: 6－77 | H24: 861－8060 | I24: 松本秀雄
A25: =ROW()-2 -> 23 | B25: 1 | C25: 3 | D25: =IF(AND(B24=B25,C24=C25),D24+1,1) -> 6 | F25: 武藤親弘 | G25: 6－77 | H25: 861－5829
A26: =ROW()-2 -> 24 | B26: 1 | C26: 3 | D26: =IF(AND(B25=B26,C25=C26),D25+1,1) -> 7 | F26: 串一 | G26: 6－77 | H26: 861－2733 | I26: 中村太一
A27: =ROW()-2 -> 25 | B27: 1 | C27: 3 | D27: =IF(AND(B26=B27,C26=C27),D26+1,1) -> 8 | F27: AJITO中村みどり | G27: 6－77 | H27: 887－0676
A28: =ROW()-2 -> 26 | B28: 1 | C28: 4 | D28: =IF(AND(B27=B28,C27=C28),D27+1,1) -> 1 | F28: 澤登武文 | G28: 6－75 | H28: 861－4214 | I28: R4 弘志さん逝去
A29: =ROW()-2 -> 27 | B29: 1 | C29: 4 | D29: =IF(AND(B28=B29,C28=C29),D28+1,1) -> 2 | E29: ● | F29: 秋山芳美 | G29: 6－74 | H29: 861－7234
A30: =ROW()-2 -> 28 | B30: 1 | C30: 4 | D30: =IF(AND(B29=B30,C29=C30),D29+1,1) -> 3 | F30: 櫻井治 | G30: 6－74 | H30: 861－2490
A31: =ROW()-2 -> 29 | B31: 1 | C31: 4 | D31: =IF(AND(B30=B31,C30=C31),D30+1,1) -> 4 | F31: 松永彰 | G31: 6－74 | H31: 861－2132 | I31: プレミール
A32: =ROW()-2 -> 30 | B32: 1 | C32: 4 | D32: =IF(AND(B31=B32,C31=C32),D31+1,1) -> 5 | F32: 橋本勇 | G32: 6－74 | H32: 861－2905
A33: =ROW()-2 -> 31 | B33: 1 | C33: 4 | D33: =IF(AND(B32=B33,C32=C33),D32+1,1) -> 6 | F33: 瀧下なつみ | G33: 6－75 | H33: 080-5417-6576 | I33: R1.4〜スズサンマンション302
A34: =ROW()-2 -> 32 | B34: 1 | C34: 5 | D34: =IF(AND(B33=B34,C33=C34),D33+1,1) -> 1 | E34: ● | F34: 鈴木洋一 | G34: 6－66－４ G3 | H34: 090-8506-2232 | I34: 102号室（861-8656）
A35: =ROW()-2 -> 33 | B35: 1 | C35: 5 | D35: =IF(AND(B34=B35,C34=C35),D34+1,1) -> 2 | F35: 首藤睦 | G35: 6－66－４ G3 | H35: 861－9056 | I35: 203号室
A36: =ROW()-2 -> 34 | B36: 1 | C36: 5 | D36: =IF(AND(B35=B36,C35=C36),D35+1,1) -> 3 | F36: 大野誠治 | G36: 6－66－４ G3 | H36: 861－8652 | I36: 403号室
A37: =ROW()-2 -> 35 | B37: 1 | C37: 6 | D37: =IF(AND(B36=B37,C36=C37),D36+1,1) -> 1 | F37: 青山啓二 | G37: 6－66 | H37: 861－3697
A38: =ROW()-2 -> 36 | B38: 1 | C38: 6 | D38: =IF(AND(B37=B38,C37=C38),D37+1,1) -> 2 | F38: 西田善隆 | G38: 6－70 | H38: 861－6352
A39: =ROW()-2 -> 37 | B39: 1 | C39: 6 | D39: =IF(AND(B38=B39,C38=C39),D38+1,1) -> 3 | F39: 渡戸正志 | G39: 6－70 | H39: 861－8128
A40: =ROW()-2 -> 38 | B40: 1 | C40: 6 | D40: =IF(AND(B39=B40,C39=C40),D39+1,1) -> 4 | F40: 冨田剛 | G40: 6-63-27 | H40: 090-7828-7469 | I40: H31.1-
...

Sheet ②差し込み印刷用４段
A1: 区 | B1: 班 | E1: 氏名 ／ 屋号 | F1: 備考 | G1: 区 | H1: 班 | K1: 氏名 ／ 屋号 | L1: 備考 | M1: 区 | N1: 班 | Q1: 氏名 ／ 屋号 | R1: 備考 | S1: 区 | T1: 班 | W1: 氏名 ／ 屋号 | X1: 備考 | Y1: トータル
A2: =①会員名簿マスタ!B3 -> 1 | B2: =①会員名簿マスタ!C3 -> 1 | C2: =①会員名簿マスタ!D3 -> 1 | D2: =①会員名簿マスタ!E3 -> 0 | E2: =①会員名簿マスタ!F3 -> 中村芳朗 | G2: =①会員名簿マスタ!B48 -> 1 | H2: =①会員名簿マスタ!C48 -> 7 | I2: =①会員名簿マスタ!D48 -> 5 | J2: =①会員名簿マスタ!E48 -> 0 | K2: =①会員名簿マスタ!F48 -> 中村未紀 | M2: =①会員名簿マスタ!B93 -> 2 | N2: =①会員名簿マスタ!C93 -> 1 | O2: =①会員名簿マスタ!D93 -> 1 | P2: =①会員名簿マスタ!E93 -> 0 | Q2: =①会員名簿マスタ!F93 -> 森田眞由美 | S2: =①会員名簿マスタ!B138 -> 2 | T2: =①会員名簿マスタ!C138 -> 7 | U2: =①会員名簿マスタ!D138 -> 9 | V2: =①会員名簿マスタ!E138 -> 0 | W2: =①会員名簿マスタ!F138 -> 藤谷健太 | Y2: 1
A3: =①会員名簿マスタ!B4 -> 1 | B3: =①会員名簿マスタ!C4 -> 1 | C3: =①会員名簿マスタ!D4 -> 2 | D3: =①会員名簿マスタ!E4 -> 0 | E3: =①会員名簿マスタ!F4 -> 中村治子 | G3: =①会員名簿マスタ!B49 -> 1 | H3: =①会員名簿マスタ!C49 -> 8 | I3: =①会員名簿マスタ!D49 -> 1 | J3: =①会員名簿マスタ!E49 -> 0 | K3: =①会員名簿マスタ!F49 -> 齋藤良一 | M3: =①会員名簿マスタ!B94 -> 2 | N3: =①会員名簿マスタ!C94 -> 1 | O3: =①会員名簿マスタ!D94 -> 2 | P3: =①会員名簿マスタ!E94 -> 0 | Q3: =①会員名簿マスタ!F94 -> 森田章裕 | S3: =①会員名簿マスタ!B139 -> 2 | T3: =①会員名簿マスタ!C139 -> 8 | U3: =①会員名簿マスタ!D139 -> 1 | V3: =①会員名簿マスタ!E139 -> ● | W3: =①会員名簿マスタ!F139 -> 佐藤和朗 | Y3: =Y2+1 -> 2
A4: =①会員名簿マスタ!B5 -> 1 | B4: =①会員名簿マスタ!C5 -> 1 | C4: =①会員名簿マスタ!D5 -> 3 | D4: =①会員名簿マスタ!E5 -> 0 | E4: =①会員名簿マスタ!F5 -> 松川正士 | G4: =①会員名簿マスタ!B50 -> 1 | H4: =①会員名簿マスタ!C50 -> 8 | I4: =①会員名簿マスタ!D50 -> 2 | J4: =①会員名簿マスタ!E50 -> 0 | K4: =①会員名簿マスタ!F50 -> 齋藤和枝 | M4: =①会員名簿マスタ!B95 -> 2 | N4: =①会員名簿マスタ!C95 -> 1 | O4: =①会員名簿マスタ!D95 -> 3 | P4: =①会員名簿マスタ!E95 -> 0 | Q4: =①会員名簿マスタ!F95 -> 小澤正行 | S4: =①会員名簿マスタ!B140 -> 2 | T4: =①会員名簿マスタ!C140 -> 8 | U4: =①会員名簿マスタ!D140 -> 2 | V4: =①会員名簿マスタ!E140 -> 0 | W4: =①会員名簿マスタ!F140 -> 爲廣哲朗 | Y4: =Y3+1 -> 3
A5: =①会員名簿マスタ!B6 -> 1 | B5: =①会員名簿マスタ!C6 -> 1 | C5: =①会員名簿マスタ!D6 -> 4 | D5: =①会員名簿マスタ!E6 -> 0 | E5: =①会員名簿マスタ!F6 -> 和田薪 | G5: =①会員名簿マスタ!B51 -> 1 | H5: =①会員名簿マスタ!C51 -> 8 | I5: =①会員名簿マスタ!D51 -> 3 | J5: =①会員名簿マスタ!E51 -> ● | K5: =①会員名簿マスタ!F51 -> 溝口美代子 | M5: =①会員名簿マスタ!B96 -> 2 | N5: =①会員名簿マスタ!C96 -> 1 | O5: =①会員名簿マスタ!D96 -> 4 | P5: =①会員名簿マスタ!E96 -> 0 | Q5: =①会員名簿マスタ!F96 -> 福島紀一 | S5: =①会員名簿マスタ!B141 -> 2 | T5: =①会員名簿マスタ!C141 -> 8 | U5: =①会員名簿マスタ!D141 -> 3 | V5: =①会員名簿マスタ!E141 -> 0 | W5: =①会員名簿マスタ!F141 -> 中根佳江 | Y5: =Y4+1 -> 4
A6: =①会員名簿マスタ!B7 -> 1 | B6: =①会員名簿マスタ!C7 -> 1 | C6: =①会員名簿マスタ!D7 -> 5 | D6: =①会員名簿マスタ!E7 -> 0 | E6: =①会員名簿マスタ!F7 -> 平井進 | G6: =①会員名簿マスタ!B52 -> 1 | H6: =①会員名簿マスタ!C52 -> 8 | I6: =①会員名簿マスタ!D52 -> 4 | J6: =①会員名簿マスタ!E52 -> 0 | K6: =①会員名簿マスタ!F52 -> 宮川正子 | M6: =①会員名簿マスタ!B97 -> 2 | N6: =①会員名簿マスタ!C97 -> 1 | O6: =①会員名簿マスタ!D97 -> 5 | P6: =①会員名簿マスタ!E97 -> 0 | Q6: =①会員名簿マスタ!F97 -> 名取眞代 | S6: =①会員名簿マスタ!B142 -> 2 | T6: =①会員名簿マスタ!C142 -> 8 | U6: =①会員名簿マスタ!D142 -> 4 | V6: =①会員名簿マスタ!E142 -> 0 | W6: =①会員名簿マスタ!F142 -> 大塚孝史 | Y6: =Y5+1 -> 5
A7: =①会員名簿マスタ!B8 -> 1 | B7: =①会員名簿マスタ!C8 -> 1 | C7: =①会員名簿マスタ!D8 -> 6 | D7: =①会員名簿マスタ!E8 -> 0 | E7: =①会員名簿マスタ!F8 -> 長谷川聡 | G7: =①会員名簿マスタ!B53 -> 1 | H7: =①会員名簿マスタ!C53 -> 8 | I7: =①会員名簿マスタ!D53 -> 5 | J7: =①会員名簿マスタ!E53 -> 0 | K7: =①会員名簿マスタ!F53 -> 佐々木由香里 | M7: =①会員名簿マスタ!B98 -> 2 | N7: =①会員名簿マスタ!C98 -> 1 | O7: =①会員名簿マスタ!D98 -> 6 | P7: =①会員名簿マスタ!E98 -> ● | Q7: =①会員名簿マスタ!F98 -> 藤田将作 | S7: =①会員名簿マスタ!B143 -> 2 | T7: =①会員名簿マスタ!C143 -> 8 | U7: =①会員名簿マスタ!D143 -> 5 | V7: =①会員名簿マスタ!E143 -> 0 | W7: =①会員名簿マスタ!F143 -> 鴨崎昶美 | Y7: =Y6+1 -> 6
A8: =①会員名簿マスタ!B9 -> 1 | B8: =①会員名簿マスタ!C9 -> 1 | C8: =①会員名簿マスタ!D9 -> 7 | D8: =①会員名簿マスタ!E9 -> 0 | E8: =①会員名簿マスタ!F9 -> 粟飯原功 | G8: =①会員名簿マスタ!B54 -> 1 | H8: =①会員名簿マスタ!C54 -> 8 | I8: =①会員名簿マスタ!D54 -> 6 | J8: =①会員名簿マスタ!E54 -> 0 | K8: =①会員名簿マスタ!F54 -> 橘鷹裕介 | M8: =①会員名簿マスタ!B99 -> 2 | N8: =①会員名簿マスタ!C99 -> 1 | O8: =①会員名簿マスタ!D99 -> 7 | P8: =①会員名簿マスタ!E99 -> 0 | Q8: =①会員名簿マスタ!F99 -> 滝本春香 | S8: =①会員名簿マスタ!B144 -> 2 | T8: =①会員名簿マスタ!C144 -> 8 | U8: =①会員名簿マスタ!D144 -> 6 | V8: =①会員名簿マスタ!E144 -> 0 | W8: =①会員名簿マスタ!F144 -> 杉本一久 | Y8: =Y7+1 -> 7
A9: =①会員名簿マスタ!B10 -> 1 | B9: =①会員名簿マスタ!C10 -> 1 | C9: =①会員名簿マスタ!D10 -> 8 | D9: =①会員名簿マスタ!E10 -> 0 | E9: =①会員名簿マスタ!F10 -> 高橋正 | G9: =①会員名簿マスタ!B55 -> 1 | H9: =①会員名簿マスタ!C55 -> 8 | I9: =①会員名簿マスタ!D55 -> 7 | J9: =①会員名簿マスタ!E55 -> 0 | K9: =①会員名簿マスタ!F55 -> 玉田義輝 | M9: =①会員名簿マスタ!B100 -> 2 | N9: =①会員名簿マスタ!C100 -> 2 | O9: =①会員名簿マスタ!D100 -> 1 | P9: =①会員名簿マスタ!E100 -> 0 | Q9: =①会員名簿マスタ!F100 -> 渡辺嘉久也 | S9: =①会員名簿マスタ!B145 -> 2 | T9: =①会員名簿マスタ!C145 -> 9 | U9: =①会員名簿マスタ!D145 -> 1 | V9: =①会員名簿マスタ!E145 -> 0 | W9: =①会員名簿マスタ!F145 -> 内山巧 | Y9: =Y8+1 -> 8
A10: =①会員名簿マスタ!B11 -> 1 | B10: =①会員名簿マスタ!C11 -> 1 | C10: =①会員名簿マスタ!D11 -> 9 | D10: =①会員名簿マスタ!E11 -> ● | E10: =①会員名簿マスタ!F11 -> 林信行 | G10: =①会員名簿マスタ!B56 -> 1 | H10: =①会員名簿マスタ!C56 -> 9 | I10: =①会員名簿マスタ!D56 -> 1 | J10: =①会員名簿マスタ!E56 -> ● | K10: =①会員名簿マスタ!F56 -> 金子勲 | M10: =①会員名簿マスタ!B101 -> 2 | N10: =①会員名簿マスタ!C101 -> 2 | O10: =①会員名簿マスタ!D101 -> 2 | P10: =①会員名簿マスタ!E101 -> 0 | Q10: =①会員名簿マスタ!F101 -> 佐野和弘 | S10: =①会員名簿マスタ!B146 -> 2 | T10: =①会員名簿マスタ!C146 -> 9 | U10: =①会員名簿マスタ!D146 -> 2 | V10: =①会員名簿マスタ!E146 -> 0 | W10: =①会員名簿マスタ!F146 -> 稲橋義治 | Y10: =Y9+1 -> 9
A11: =①会員名簿マスタ!B12 -> 1 | B11: =①会員名簿マスタ!C12 -> 2 | C11: =①会員名簿マスタ!D12 -> 1 | D11: =①会員名簿マスタ!E12 -> 0 | E11: =①会員名簿マスタ!F12 -> 紺野建設 | G11: =①会員名簿マスタ!B57 -> 1 | H11: =①会員名簿マスタ!C57 -> 9 | I11: =①会員名簿マスタ!D57 -> 2 | J11: =①会員名簿マスタ!E57 -> 0 | K11: =①会員名簿マスタ!F57 -> 松本弘子 | M11: =①会員名簿マスタ!B102 -> 2 | N11: =①会員名簿マスタ!C102 -> 2 | O11: =①会員名簿マスタ!D102 -> 3 | P11: =①会員名簿マスタ!E102 -> 0 | Q11: =①会員名簿マスタ!F102 -> 橋本岳 | S11: =①会員名簿マスタ!B147 -> 2 | T11: =①会員名簿マスタ!C147 -> 9 | U11: =①会員名簿マスタ!D147 -> 3 | V11: =①会員名簿マスタ!E147 -> ● | W11: =①会員名簿マスタ!F147 -> 堀江善幸 | Y11: =Y10+1 -> 10
A12: =①会員名簿マスタ!B13 -> 1 | B12: =①会員名簿マスタ!C13 -> 2 | C12: =①会員名簿マスタ!D13 -> 2 | D12: =①会員名簿マスタ!E13 -> 0 | E12: =①会員名簿マスタ!F13 -> 遠山悦子 | G12: =①会員名簿マスタ!B58 -> 1 | H12: =①会員名簿マスタ!C58 -> 9 | I12: =①会員名簿マスタ!D58 -> 3 | J12: =①会員名簿マスタ!E58 -> 0 | K12: =①会員名簿マスタ!F58 -> 関口香奈 | M12: =①会員名簿マスタ!B103 -> 2 | N12: =①会員名簿マスタ!C103 -> 2 | O12: =①会員名簿マスタ!D103 -> 4 | P12: =①会員名簿マスタ!E103 -> 0 | Q12: =①会員名簿マスタ!F103 -> 御薗節子 | S12: =①会員名簿マスタ!B148 -> 2 | T12: =①会員名簿マスタ!C148 -> 9 | U12: =①会員名簿マスタ!D148 -> 4 | V12: =①会員名簿マスタ!E148 -> 0 | W12: =①会員名簿マスタ!F148 -> 水内鶴男 | Y12: =Y11+1 -> 11
A13: =①会員名簿マスタ!B14 -> 1 | B13: =①会員名簿マスタ!C14 -> 2 | C13: =①会員名簿マスタ!D14 -> 3 | D13: =①会員名簿マスタ!E14 -> 0 | E13: =①会員名簿マスタ!F14 -> 高瀬一 | G13: =①会員名簿マスタ!B59 -> 1 | H13: =①会員名簿マスタ!C59 -> 9 | I13: =①会員名簿マスタ!D59 -> 4 | J13: =①会員名簿マスタ!E59 -> 0 | K13: =①会員名簿マスタ!F59 -> 藤田範男 | M13: =①会員名簿マスタ!B104 -> 2 | N13: =①会員名簿マスタ!C104 -> 2 | O13: =①会員名簿マスタ!D104 -> 5 | P13: =①会員名簿マスタ!E104 -> ● | Q13: =①会員名簿マスタ!F104 -> 小松誠 | S13: =①会員名簿マスタ!B149 -> 2 | T13: =①会員名簿マスタ!C149 -> 9 | U13: =①会員名簿マスタ!D149 -> 5 | V13: =①会員名簿マスタ!E149 -> 0 | W13: =①会員名簿マスタ!F149 -> 阿部治 | Y13: =Y12+1 -> 12
A14: =①会員名簿マスタ!B15 -> 1 | B14: =①会員名簿マスタ!C15 -> 2 | C14: =①会員名簿マスタ!D15 -> 4 | D14: =①会員名簿マスタ!E15 -> ● | E14: =①会員名簿マスタ!F15 -> 齋藤勇 | G14: =①会員名簿マスタ!B60 -> 1 | H14: =①会員名簿マスタ!C60 -> 9 | I14: =①会員名簿マスタ!D60 -> 5 | J14: =①会員名簿マスタ!E60 -> 0 | K14: =①会員名簿マスタ!F60 -> 前田清孝 | M14: =①会員名簿マスタ!B105 -> 2 | N14: =①会員名簿マスタ!C105 -> 3 | O14: =①会員名簿マスタ!D105 -> 1 | P14: =①会員名簿マスタ!E105 -> 0 | Q14: =①会員名簿マスタ!F105 -> 霜村紀子 | S14: =①会員名簿マスタ!B150 -> 2 | T14: =①会員名簿マスタ!C150 -> 9 | U14: =①会員名簿マスタ!D150 -> 6 | V14: =①会員名簿マスタ!E150 -> 0 | W14: =①会員名簿マスタ!F150 -> 八子秀五郎 | Y14: =Y13+1 -> 13
... A17: =①会員名簿マスタ!B18 -> 1 | B17: =①会員名簿マスタ!C18 -> 2 | C17: =①会員名簿マスタ!D18 -> 7 | D17: =①会員名簿マスタ!E18 -> 0 | E17: =①会員名簿マスタ!F18 -> 佐藤清 | G17: =①会員名簿マスタ!B63 -> 1 | H17: =①会員名簿マスタ!C63 -> 9 | I17: =①会員名簿マスタ!D63 -> 8 | J17: =①会員名簿マスタ!E63 -> 0 | K17: =①会員名簿マスタ!F63 -> 前田拓也 | M17: =①会員名簿マスタ!B108 -> 2 | N17: =①会員名簿マスタ!C108 -> 3 | O17: =①会員名簿マスタ!D108 -> 4 | P17: =①会員名簿マスタ!E108 -> ● | Q17: =①会員名簿マスタ!F108 -> 網倉潤子 | S17: =①会員名簿マスタ!B153 -> 2 | T17: =①会員名簿マスタ!C153 -> 10 | U17: =①会員名簿マスタ!D153 -> 1 | V17: =①会員名簿マスタ!E153 -> 0 | W17: =①会員名簿マスタ!F153 -> 金井六平 | Y17: =Y16+1 -> 16
A18: =①会員名簿マスタ!B19 -> 1 | B18: =①会員名簿マスタ!C19 -> 2 | C18: =①会員名簿マスタ!D19 -> 8 | D18: =①会員名簿マスタ!E19 -> 0 | E18: =①会員名簿マスタ!F19 -> 戸村則登 | G18: =①会員名簿マスタ!B64 -> 1 | H18: =①会員名簿マスタ!C64 -> 9 | I18: =①会員名簿マスタ!D64 -> 9 | J18: =①会員名簿マスタ!E64 -> 0 | K18: =①会員名簿マスタ!F64 -> 竹本久子 | M18: =①会員名簿マスタ!B109 -> 2 | N18: =①会員名簿マスタ!C109 -> 3 | O18: =①会員名簿マスタ!D109 -> 5 | P18: =①会員名簿マスタ!E109 -> 0 | Q18: =①会員名簿マスタ!F109 -> 上田千代 | R18: 対象外 | S18: =①会員名簿マスタ!B154 -> 2 | T18: =①会員名簿マスタ!C154 -> 10 | U18: =①会員名簿マスタ!D154 -> 2 | V18: =①会員名簿マスタ!E154 -> 0 | W18: =①会員名簿マスタ!F154 -> 小池弘 | Y18: =Y17+1 -> 17
A19: =①会員名簿マスタ!B20 -> 1 | B19: =①会員名簿マスタ!C20 -> 3 | C19: =①会員名簿マスタ!D20 -> 1 | D19: =①会員名簿マスタ!E20 -> ● | E19: =①会員名簿マスタ!F20 -> 佐久間明 | G19: =①会員名簿マスタ!B65 -> 1 | H19: =①会員名簿マスタ!C65 -> 10 | I19: =①会員名簿マスタ!D65 -> 1 | J19: =①会員名簿マスタ!E65 -> 0 | K19: =①会員名簿マスタ!F65 -> 須田昭 | M19: =①会員名簿マスタ!B110 -> 2 | N19: =①会員名簿マスタ!C110 -> 3 | O19: =①会員名簿マスタ!D110 -> 6 | P19: =①会員名簿マスタ!E110 -> 0 | Q19: =①会員名簿マスタ!F110 -> 磯野真一 | S19: =①会員名簿マスタ!B155 -> 2 | T19: =①会員名簿マスタ!C155 -> 10 | U19: =①会員名簿マスタ!D155 -> 3 | V19: =①会員名簿マスタ!E155 -> 0 | W19: =①会員名簿マスタ!F155 -> 多和エイ子 | Y19: =Y18+1 -> 18
A20: =①会員名簿マスタ!B21 -> 1 | B20: =①会員名簿マスタ!C21 -> 3 | C20: =①会員名簿マスタ!D21 -> 2 | D20: =①会員名簿マスタ!E21 -> 0 | E20: =①会員名簿マスタ!F21 -> 鳥居スミヱ | G20: =①会員名簿マスタ!B66 -> 1 | H20: =①会員名簿マスタ!C66 -> 10 | I20: =①会員名簿マスタ!D66 -> 2 | J20: =①会員名簿マスタ!E66 -> 0 | K20: =①会員名簿マスタ!F66 -> 福寿早苗 | M20: =①会員名簿マスタ!B111 -> 2 | N20: =①会員名簿マスタ!C111 -> 4 | O20: =①会員名簿マスタ!D111 -> 1 | P20: =①会員名簿マスタ!E111 -> 0 | Q20: =①会員名簿マスタ!F111 -> 岩垂晴夫 | S20: =①会員名簿マスタ!B156 -> 2 | T20: =①会員名簿マスタ!C156 -> 10 | U20: =①会員名簿マスタ!D156 -> 4 | V20: =①会員名簿マスタ!E156 -> 0 | W20: =①会員名簿マスタ!F156 -> 橋本尚弥 | Y20: =Y19+1 -> 19
A21: =①会員名簿マスタ!B22 -> 1 | B21: =①会員名簿マスタ!C22 -> 3 | C21: =①会員名簿マスタ!D22 -> 3 | D21: =①会員名簿マスタ!E22 -> 0 | E21: =①会員名簿マスタ!F22 -> 渋江康弘 | G21: =①会員名簿マスタ!B67 -> 1 | H21: =①会員名簿マスタ!C67 -> 10 | I21: =①会員名簿マスタ!D67 -> 3 | J21: =①会員名簿マスタ!E67 -> 0 | K21: =①会員名簿マスタ!F67 -> 小山米子 | M21: =①会員名簿マスタ!B112 -> 2 | N21: =①会員名簿マスタ!C112 -> 4 | O21: =①会員名簿マスタ!D112 -> 2 | P21: =①会員名簿マスタ!E112 -> 0 | Q21: =①会員名簿マスタ!F112 -> 斉田芳久 | S21: =①会員名簿マスタ!B157 -> 2 | T21: =①会員名簿マスタ!C157 -> 10 | U21: =①会員名簿マスタ!D157 -> 5 | V21: =①会員名簿マスタ!E157 -> 0 | W21: =①会員名簿マスタ!F157 -> 藤巻明子 | Y21: =Y20+1 -> 20
A22: =①会員名簿マスタ!B23 -> 1 | B22: =①会員名簿マスタ!C23 -> 3 | C22: =①会員名簿マスタ!D23 -> 4 | D22: =①会員名簿マスタ!E23 -> 0 | E22: =①会員名簿マスタ!F23 -> 石岡明憲 | G22: =①会員名簿マスタ!B68 -> 1 | H22: =①会員名簿マスタ!C68 -> 10 | I22: =①会員名簿マスタ!D68 -> 4 | J22: =①会員名簿マスタ!E68 -> ● | K22: =①会員名簿マスタ!F68 -> 須田公子 | M22: =①会員名簿マスタ!B113 -> 2 | N22: =①会員名簿マスタ!C113 -> 4 | O22: =①会員名簿マスタ!D113 -> 3 | P22: =①会員名簿マスタ!E113 -> 0 | Q22: =①会員名簿マスタ!F113 -> 安藤豊美 | S22: =①会員名簿マスタ!B158 -> 2 | T22: =①会員名簿マスタ!C158 -> 10 | U22: =①会員名簿マスタ!D158 -> 6 | V22: =①会員名簿マスタ!E158 -> 0 | W22: =①会員名簿マスタ!F158 -> 鈴木由美子 | Y22: =Y21+1 -> 21
A23: =①会員名簿マスタ!B24 -> 1 | B23: =①会員名簿マスタ!C24 -> 3 | C23: =①会員名簿マスタ!D24 -> 5 | D23: =①会員名簿マスタ!E24 -> 0 | E23: =①会員名簿マスタ!F24 -> 中華料理成都 | G23: =①会員名簿マスタ!B69 -> 1 | H23: =①会員名簿マスタ!C69 -> 11 | I23: =①会員名簿マスタ!D69 -> 1 | J23: =①会員名簿マスタ!E69 -> 0 | K23: =①会員名簿マスタ!F69 -> 渡邊芳彦 | M23: =①会員名簿マスタ!B114 -> 2 | N23: =①会員名簿マスタ!C114 -> 4 | O23: =①会員名簿マスタ!D114 -> 4 | P23: =①会員名簿マスタ!E114 -> ● | Q23: =①会員名簿マスタ!F114 -> 濱名誠 | S23: =①会員名簿マスタ!B159 -> 2 | T23: =①会員名簿マスタ!C159 -> 10 | U23: =①会員名簿マスタ!D159 -> 7 | V23: =①会員名簿マスタ!E159 -> 0 | W23: =①会員名簿マスタ!F159 -> 澤藤成穂 | Y23: =Y22+1 -> 22
A24: =①会員名簿マスタ!B25 -> 1 | B24: =①会員名簿マスタ!C25 -> 3 | C24: =①会員名簿マスタ!D25 -> 6 | D24: =①会員名簿マスタ!E25 -> 0 | E24: =①会員名簿マスタ!F25 -> 武藤親弘 | G24: =①会員名簿マスタ!B70 -> 1 | H24: =①会員名簿マスタ!C70 -> 11 | I24: =①会員名簿マスタ!D70 -> 2 | J24: =①会員名簿マスタ!E70 -> 0 | K24: =①会員名簿マスタ!F70 -> 乾タツ子 | M24: =①会員名簿マスタ!B115 -> 2 | N24: =①会員名簿マスタ!C115 -> 4 | O24: =①会員名簿マスタ!D115 -> 5 | P24: =①会員名簿マスタ!E115 -> 0 | Q24: =①会員名簿マスタ!F115 -> 佐藤シズエ | S24: =①会員名簿マスタ!B160 -> 2 | T24: =①会員名簿マスタ!C160 -> 10 | U24: =①会員名簿マスタ!D160 -> 8 | V24: =①会員名簿マスタ!E160 -> 0 | W24: =①会員名簿マスタ!F160 -> 中島京子 | Y24: =Y23+1 -> 23
A25: =①会員名簿マスタ!B26 -> 1 | B25: =①会員名簿マスタ!C26 -> 3 | C25: =①会員名簿マスタ!D26 -> 7 | D25: =①会員名簿マスタ!E26 -> 0 | E25: =①会員名簿マスタ!F26 -> 串一 | G25: =①会員名簿マスタ!B71 -> 1 | H25: =①会員名簿マスタ!C71 -> 11 | I25: =①会員名簿マスタ!D71 -> 3 | J25: =①会員名簿マスタ!E71 -> 0 | K25: =①会員名簿マスタ!F71 -> 矢部謙三 | M25: =①会員名簿マスタ!B116 -> 2 | N25: =①会員名簿マスタ!C116 -> 5 | O25: =①会員名簿マスタ!D116 -> 1 | P25: =①会員名簿マスタ!E116 -> 0 | Q25: =①会員名簿マスタ!F116 -> 森原智 | S25: =①会員名簿マスタ!B161 -> 2 | T25: =①会員名簿マスタ!C161 -> 10 | U25: =①会員名簿マスタ!D161 -> 9 | V25: =①会員名簿マスタ!E161 -> ● | W25: =①会員名簿マスタ!F161 -> 軍司由利子 | Y25: =Y24+1 -> 24
A26: =①会員名簿マスタ!B27 -> 1 | B26: =①会員名簿マスタ!C27 -> 3 | C26: =①会員名簿マスタ!D27 -> 8 | D26: =①会員名簿マスタ!E27 -> 0 | E26: =①会員名簿マスタ!F27 -> AJITO中村みどり | G26: =①会員名簿マスタ!B72 -> 1 | H26: =①会員名簿マスタ!C72 -> 11 | I26: =①会員名簿マスタ!D72 -> 4 | J26: =①会員名簿マスタ!E72 -> 0 | K26: =①会員名簿マスタ!F72 -> 千葉幸代 | M26: =①会員名簿マスタ!B117 -> 2 | N26: =①会員名簿マスタ!C117 -> 5 | O26: =①会員名簿マスタ!D117 -> 2 | P26: =①会員名簿マスタ!E117 -> ● | Q26: =①会員名簿マスタ!F117 -> 岡本三七子 | S26: =①会員名簿マスタ!B162 -> 2 | T26: =①会員名簿マスタ!C162 -> 10 | U26: =①会員名簿マスタ!D162 -> 10 | V26: =①会員名簿マスタ!E162 -> 0 | W26: =①会員名簿マスタ!F162 -> 内田純久 | Y26: =Y25+1 -> 25
A27: =①会員名簿マスタ!B28 -> 1 | B27: =①会員名簿マスタ!C28 -> 4 | C27: =①会員名簿マスタ!D28 -> 1 | D27: =①会員名簿マスタ!E28 -> 0 | E27: =①会員名簿マスタ!F28 -> 澤登武文 | G27: =①会員名簿マスタ!B73 -> 1 | H27: =①会員名簿マスタ!C73 -> 11 | I27: =①会員名簿マスタ!D73 -> 5 | J27: =①会員名簿マスタ!E73 -> 0 | K27: =①会員名簿マスタ!F73 -> 杉澤知美 | M27: =①会員名簿マスタ!B118 -> 2 | N27: =①会員名簿マスタ!C118 -> 5 | O27: =①会員名簿マスタ!D118 -> 3 | P27: =①会員名簿マスタ!E118 -> 0 | Q27: =①会員名簿マスタ!F118 -> 佐々木誠 | S27: =①会員名簿マスタ!B163 -> 2 | T27: =①会員名簿マスタ!C163 -> 10 | U27: =①会員名簿マスタ!D163 -> 11 | V27: =①会員名簿マスタ!E163 -> 0 | W27: =①会員名簿マスタ!F163 -> 稲葉政志 | Y27: =Y26+1 -> 26
A28: =①会員名簿マスタ!B29 -> 1 | B28: =①会員名簿マスタ!C29 -> 4 | C28: =①会員名簿マスタ!D29 -> 2 | D28: =①会員名簿マスタ!E29 -> ● | E28: =①会員名簿マスタ!F29 -> 秋山芳美 | G28: =①会員名簿マスタ!B74 -> 1 | H28: =①会員名簿マスタ!C74 -> 11 | I28: =①会員名簿マスタ!D74 -> 6 | J28: =①会員名簿マスタ!E74 -> 0 | K28: =①会員名簿マスタ!F74 -> 伊藤健二 | M28: =①会員名簿マスタ!B119 -> 2 | N28: =①会員名簿マスタ!C119 -> 5 | O28: =①会員名簿マスタ!D119 -> 4 | P28: =①会員名簿マスタ!E119 -> 0 | Q28: =①会員名簿マスタ!F119 -> 鹿野絵里子 | S28: =①会員名簿マスタ!B164 -> 2 | T28: =①会員名簿マスタ!C164 -> 11 | U28: =①会員名簿マスタ!D164 -> 1 | V28: =①会員名簿マスタ!E164 -> 0 | W28: =①会員名簿マスタ!F164 -> 赤荻忠幸 | Y28: =Y27+1 -> 27
A29: =①会員名簿マスタ!B30 -> 1 | B29: =①会員名簿マスタ!C30 -> 4 | C29: =①会員名簿マスタ!D30 -> 3 | D29: =①会員名簿マスタ!E30 -> 0 | E29: =①会員名簿マスタ!F30 -> 櫻井治 | G29: =①会員名簿マスタ!B75 -> 1 | H29: =①会員名簿マスタ!C75 -> 11 | I29: =①会員名簿マスタ!D75 -> 7 | J29: =①会員名簿マスタ!E75 -> ● | K29: =①会員名簿マスタ!F75 -> 荒井照男 | M29: =①会員名簿マスタ!B120 -> 2 | N29: =①会員名簿マスタ!C120 -> 5 | O29: =①会員名簿マスタ!D120 -> 5 | P29: =①会員名簿マスタ!E120 -> 0 | Q29: =①会員名簿マスタ!F120 -> 田口英弼 | S29: =①会員名簿マスタ!B165 -> 2 | T29: =①会員名簿マスタ!C165 -> 11 | U29: =①会員名簿マスタ!D165 -> 2 | V29: =①会員名簿マスタ!E165 -> 0 | W29: =①会員名簿マスタ!F165 -> 山下信子 | Y29: =Y28+1 -> 28
A30: =①会員名簿マスタ!B31 -> 1 | B30: =①会員名簿マスタ!C31 -> 4 | C30: =①会員名簿マスタ!D31 -> 4 | D30: =①会員名簿マスタ!E31 -> 0 | E30: =①会員名簿マスタ!F31 -> 松永彰 | G30: =①会員名簿マスタ!B76 -> 1 | H30: =①会員名簿マスタ!C76 -> 11 | I30: =①会員名簿マスタ!D76 -> 8 | J30: =①会員名簿マスタ!E76 -> 0 | K30: =①会員名簿マスタ!F76 -> 佐々木宏子 | M30: =①会員名簿マスタ!B121 -> 2 | N30: =①会員名簿マスタ!C121 -> 5 | O30: =①会員名簿マスタ!D121 -> 6 | P30: =①会員名簿マスタ!E121 -> 0 | Q30: =①会員名簿マスタ!F121 -> 倉邉雅光 | S30: =①会員名簿マスタ!B166 -> 2 | T30: =①会員名簿マスタ!C166 -> 11 | U30: =①会員名簿マスタ!D166 -> 3 | V30: =①会員名簿マスタ!E166 -> ● | W30: =①会員名簿マスタ!F166 -> 伊藤一樹 | Y30: =Y29+1 -> 29
... A46: =①会員名簿マスタ!B47 -> 1 | B46: =①会員名簿マスタ!C47 -> 7 | C46: =①会員名簿マスタ!D47 -> 4 | D46: =①会員名簿マスタ!E47 -> 0 | E46: =①会員名簿マスタ!F47 -> 小野怜子 | G46: =①会員名簿マスタ!B92 -> 1 | H46: =①会員名簿マスタ!C92 -> 12 | I46: =①会員名簿マスタ!D92 -> 15 | J46: =①会員名簿マスタ!E92 -> 0 | K46: =①会員名簿マスタ!F92 -> 高橋博満 | M46: =①会員名簿マスタ!B137 -> 2 | N46: =①会員名簿マスタ!C137 -> 7 | O46: =①会員名簿マスタ!D137 -> 8 | P46: =①会員名簿マスタ!E137 -> 0 | Q46: =①会員名簿マスタ!F137 -> 小原友美 | S46: =①会員名簿マスタ!B182 -> 2 | T46: =①会員名簿マスタ!C182 -> 12 | U46: =①会員名簿マスタ!D182 -> 9 | V46: =①会員名簿マスタ!E182 -> 0 | W46: =①会員名簿マスタ!F182 -> 菅野吉幸 | Y46: =Y45+1 -> 45

Sheet ⑩寄付者一覧 (班別)
A1: R７夏季祭礼 会員寄付
A2: 通番 | B2: 区 | C2: 班 | D2: No. | E2: 評議員 | F2: 氏名 ／ 屋号 | G2: R6寄付金額 | H2: 収集日 | J2: 備 考
A3: =ROW()-2 -> 1 | B3: =①会員名簿マスタ!B3 -> 1 | C3: =①会員名簿マスタ!C3 -> 1 | D3: =IF(AND(B2=B3,C2=C3),D2+1,1) -> 1 | F3: =①会員名簿マスタ!F3 -> 中村芳朗 | G3: 1000 | H3: 45851
A4: =ROW()-2 -> 2 | B4: =①会員名簿マスタ!B4 -> 1 | C4: =①会員名簿マスタ!C4 -> 1 | D4: =IF(AND(B3=B4,C3=C4),D3+1,1) -> 2 | F4: =①会員名簿マスタ!F4 -> 中村治子 | G4: 1000 | H4: 45851
A5: =ROW()-2 -> 3 | B5: =①会員名簿マスタ!B5 -> 1 | C5: =①会員名簿マスタ!C5 -> 1 | D5: =IF(AND(B4=B5,C4=C5),D4+1,1) -> 3 | F5: =①会員名簿マスタ!F5 -> 松川正士 | G5: 5000 | H5: 45851
A6: =ROW()-2 -> 4 | B6: =①会員名簿マスタ!B6 -> 1 | C6: =①会員名簿マスタ!C6 -> 1 | D6: =IF(AND(B5=B6,C5=C6),D5+1,1) -> 4 | F6: =①会員名簿マスタ!F6 -> 和田薪 | G6: 3000 | H6: 45851
A7: =ROW()-2 -> 5 | B7: =①会員名簿マスタ!B7 -> 1 | C7: =①会員名簿マスタ!C7 -> 1 | D7: =IF(AND(B6=B7,C6=C7),D6+1,1) -> 5 | F7: =①会員名簿マスタ!F7 -> 平井進 | G7: 5000 | H7: 45851
A8: =ROW()-2 -> 6 | B8: =①会員名簿マスタ!B8 -> 1 | C8: =①会員名簿マスタ!C8 -> 1 | D8: =IF(AND(B7=B8,C7=C8),D7+1,1) -> 6 | F8: =①会員名簿マスタ!F8 -> 長谷川聡 | H8: 45851
A9: =ROW()-2 -> 7 | B9: =①会員名簿マスタ!B9 -> 1 | C9: =①会員名簿マスタ!C9 -> 1 | D9: =IF(AND(B8=B9,C8=C9),D8+1,1) -> 7 | F9: =①会員名簿マスタ!F9 -> 粟飯原功 | G9: 10000 | H9: 45851
A10: =ROW()-2 -> 8 | B10: =①会員名簿マスタ!B10 -> 1 | C10: =①会員名簿マスタ!C10 -> 1 | D10: =IF(AND(B9=B10,C9=C10),D9+1,1) -> 8 | F10: =①会員名簿マスタ!F10 -> 高橋正 | G10: 5000 | H10: 45851
A11: =ROW()-2 -> 9 | B11: =①会員名簿マスタ!B11 -> 1 | C11: =①会員名簿マスタ!C11 -> 1 | D11: =IF(AND(B10=B11,C10=C11),D10+1,1) -> 9 | E11: ● | F11: =①会員名簿マスタ!F11 -> 林信行 | G11: 5000 | H11: 45851
A12: =ROW()-2 -> 10 | B12: =①会員名簿マスタ!B12 -> 1 | C12: =①会員名簿マスタ!C12 -> 2 | D12: =IF(AND(B11=B12,C11=C12),D11+1,1) -> 1 | F12: =①会員名簿マスタ!F12 -> 紺野建設 | G12: 10000 | H12: 45851
A13: =ROW()-2 -> 11 | B13: =①会員名簿マスタ!B13 -> 1 | C13: =①会員名簿マスタ!C13 -> 2 | D13: =IF(AND(B12=B13,C12=C13),D12+1,1) -> 2 | F13: =①会員名簿マスタ!F13 -> 遠山悦子 | G13: 3000 | H13: 45851
A14: =ROW()-2 -> 12 | B14: =①会員名簿マスタ!B14 -> 1 | C14: =①会員名簿マスタ!C14 -> 2 | D14: =IF(AND(B13=B14,C13=C14),D13+1,1) -> 3 | F14: =①会員名簿マスタ!F14 -> 高瀬一 | G14: 3000 | H14: 45851
A15: =ROW()-2 -> 13 | B15: =①会員名簿マスタ!B15 -> 1 | C15: =①会員名簿マスタ!C15 -> 2 | D15: =IF(AND(B14=B15,C14=C15),D14+1,1) -> 4 | F15: =①会員名簿マスタ!F15 -> 齋藤勇 | G15: 10000 | H15: 45851
A16: =ROW()-2 -> 14 | B16: =①会員名簿マスタ!B16 -> 1 | C16: =①会員名簿マスタ!C16 -> 2 | D16: =IF(AND(B15=B16,C15=C16),D15+1,1) -> 5 | E16: ● | F16: =①会員名簿マスタ!F16 -> 鍋田益男 | G16: 3000 | H16: 45851
A17: =ROW()-2 -> 15 | B17: =①会員名簿マスタ!B17 -> 1 | C17: =①会員名簿マスタ!C17 -> 2 | D17: =IF(AND(B16=B17,C16=C17),D16+1,1) -> 6 | F17: =①会員名簿マスタ!F17 -> マミークリーニング | H17: 45851
A18: =ROW()-2 -> 16 | B18: =①会員名簿マスタ!B18 -> 1 | C18: =①会員名簿マスタ!C18 -> 2 | D18: =IF(AND(B17=B18,C17=C18),D17+1,1) -> 7 | F18: =①会員名簿マスタ!F18 -> 佐藤清 | G18: 10000 | H18: 45851
A19: =ROW()-2 -> 17 | B19: =①会員名簿マスタ!B19 -> 1 | C19: =①会員名簿マスタ!C19 -> 2 | D19: =IF(AND(B18=B19,C18=C19),D18+1,1) -> 8 | F19: =①会員名簿マスタ!F19 -> 戸村則登 | G19: 3000 | H19: 45851
A20: =ROW()-2 -> 18 | B20: =①会員名簿マスタ!B20 -> 1 | C20: =①会員名簿マスタ!C20 -> 3 | D20: =IF(AND(B19=B20,C19=C20),D19+1,1) -> 1 | F20: =①会員名簿マスタ!F20 -> 佐久間明 | G20: 10000 | H20: 45851
A21: =ROW()-2 -> 19 | B21: =①会員名簿マスタ!B21 -> 1 | C21: =①会員名簿マスタ!C21 -> 3 | D21: =IF(AND(B20=B21,C20=C21),D20+1,1) -> 2 | F21: =①会員名簿マスタ!F21 -> 鳥居スミヱ | G21: 3000 | H21: 45851
A22: =ROW()-2 -> 20 | B22: =①会員名簿マスタ!B22 -> 1 | C22: =①会員名簿マスタ!C22 -> 3 | D22: =IF(AND(B21=B22,C21=C22),D21+1,1) -> 3 | F22: =①会員名簿マスタ!F22 -> 渋江康弘 | G22: 3000 | H22: 45851
A23: =ROW()-2 -> 21 | B23: =①会員名簿マスタ!B23 -> 1 | C23: =①会員名簿マスタ!C23 -> 3 | D23: =IF(AND(B22=B23,C22=C23),D22+1,1) -> 4 | F23: =①会員名簿マスタ!F23 -> 石岡明憲 | G23: 3000 | H23: 45851
A24: =ROW()-2 -> 22 | B24: =①会員名簿マスタ!B24 -> 1 | C24: =①会員名簿マスタ!C24 -> 3 | D24: =IF(AND(B23=B24,C23=C24),D23+1,1) -> 5 | F24: =①会員名簿マスタ!F24 -> 中華料理成都 | G24: 3000 | H24: 45851
A25: =ROW()-2 -> 23 | B25: =①会員名簿マスタ!B25 -> 1 | C25: =①会員名簿マスタ!C25 -> 3 | D25: =IF(AND(B24=B25,C24=C25),D24+1,1) -> 6 | F25: =①会員名簿マスタ!F25 -> 武藤親弘 | G25: 5000 | H25: 45851
A26: =ROW()-2 -> 24 | B26: =①会員名簿マスタ!B26 -> 1 | C26: =①会員名簿マスタ!C26 -> 3 | D26: =IF(AND(B25=B26,C25=C26),D25+1,1) -> 7 | F26: =①会員名簿マスタ!F26 -> 串一 | G26: 3000 | H26: 45851
A27: =ROW()-2 -> 25 | B27: =①会員名簿マスタ!B27 -> 1 | C27: =①会員名簿マスタ!C27 -> 3 | D27: =IF(AND(B26=B27,C26=C27),D26+1,1) -> 8 | E27: ● | F27: =①会員名簿マスタ!F27 -> AJITO中村みどり | G27: 3000 | H27: 45851
A28: =ROW()-2 -> 26 | B28: =①会員名簿マスタ!B28 -> 1 | C28: =①会員名簿マスタ!C28 -> 4 | D28: =IF(AND(B27=B28,C27=C28),D27+1,1) -> 1 | F28: =①会員名簿マスタ!F28 -> 澤登武文 | G28: 1000 | H28: 45851
A29: =ROW()-2 -> 27 | B29: =①会員名簿マスタ!B29 -> 1 | C29: =①会員名簿マスタ!C29 -> 4 | D29: =IF(AND(B28=B29,C28=C29),D28+1,1) -> 2 | F29: =①会員名簿マスタ!F29 -> 秋山芳美 | G29: 1000 | H29: 45851
A30: =ROW()-2 -> 28 | B30: =①会員名簿マスタ!B30 -> 1 | C30: =①会員名簿マスタ!C30 -> 4 | D30: =IF(AND(B29=B30,C29=C30),D29+1,1) -> 3 | F30: =①会員名簿マスタ!F30 -> 櫻井治 | G30: 1000 | H30: 45851
A31: =ROW()-2 -> 29 | B31: =①会員名簿マスタ!B31 -> 1 | C31: =①会員名簿マスタ!C31 -> 4 | D31: =IF(AND(B30=B31,C30=C31),D30+1,1) -> 4 | F31: =①会員名簿マスタ!F31 -> 松永彰 | G31: 1000 | H31: 45851
A32: =ROW()-2 -> 30 | B32: =①会員名簿マスタ!B32 -> 1 | C32: =①会員名簿マスタ!C32 -> 4 | D32: =IF(AND(B31=B32,C31=C32),D31+1,1) -> 5 | F32: =①会員名簿マスタ!F32 -> 橋本勇 | G32: 1000 | H32: 45851
A33: =ROW()-2 -> 31 | B33: =①会員名簿マスタ!B33 -> 1 | C33: =①会員名簿マスタ!C33 -> 4 | D33: =IF(AND(B32=B33,C32=C33),D32+1,1) -> 6 | F33: =①会員名簿マスタ!F33 -> 瀧下なつみ | G33: 1000 | H33: 45851
A34: =ROW()-2 -> 32 | B34: =①会員名簿マスタ!B34 -> 1 | C34: =①会員名簿マスタ!C34 -> 5 | D34: =IF(AND(B33=B34,C33=C34),D33+1,1) -> 1 | F34: =①会員名簿マスタ!F34 -> 鈴木洋一 | G34: 1000 | H34: 45851
A35: =ROW()-2 -> 33 | B35: =①会員名簿マスタ!B35 -> 1 | C35: =①会員名簿マスタ!C35 -> 5 | D35: =IF(AND(B34=B35,C34=C35),D34+1,1) -> 2 | E35: ● | F35: =①会員名簿マスタ!F35 -> 首藤睦 | G35: 5000 | H35: 45851
A36: =ROW()-2 -> 34 | B36: =①会員名簿マスタ!B36 -> 1 | C36: =①会員名簿マスタ!C36 -> 5 | D36: =IF(AND(B35=B36,C35=C36),D35+1,1) -> 3 | F36: =①会員名簿マスタ!F36 -> 大野誠治 | G36: 5000 | H36: 45851
A37: =ROW()-2 -> 35 | B37: =①会員名簿マスタ!B37 -> 1 | C37: =①会員名簿マスタ!C37 -> 6 | D37: =IF(AND(B36=B37,C36=C37),D36+1,1) -> 1 | F37: =①会員名簿マスタ!F37 -> 青山啓二 | G37: 10000 | H37: 45851
A38: =ROW()-2 -> 36 | B38: =①会員名簿マスタ!B38 -> 1 | C38: =①会員名簿マスタ!C38 -> 6 | D38: =IF(AND(B37=B38,C37=C38),D37+1,1) -> 2 | E38: ● | F38: =①会員名簿マスタ!F38 -> 西田善隆 | G38: 5000 | H38: 45851
A39: =ROW()-2 -> 37 | B39: =①会員名簿マスタ!B39 -> 1 | C39: =①会員名簿マスタ!C39 -> 6 | D39: =IF(AND(B38=B39,C38=C39),D38+1,1) -> 3 | F39: =①会員名簿マスタ!F39 -> 渡戸正志 | G39: 5000 | H39: 45851
A40: =ROW()-2 -> 38 | B40: =①会員名簿マスタ!B40 -> 1 | C40: =①会員名簿マスタ!C40 -> 6 | D40: =IF(AND(B39=B40,C39=C40),D39+1,1) -> 4 | E40: ● | F40: =①会員名簿マスタ!F40 -> 冨田剛 | G40: 1000 | H40: 45851
...

Sheet ⑫返礼品配布用リスト（班別）
B1: １区１班
A2: 評議員： 林信行 | C2: 返礼チェック
A3: No. | B3: 奉納者 | C3: ☑
A4: 1 | B4: 中村芳朗
A5: =COUNTA(A$4:A4)+1 -> 2 | B5: 中村治子
A6: =COUNTA(A$4:A5)+1 -> 3 | B6: 松川正士
A7: =COUNTA(A$4:A6)+1 -> 4 | B7: 和田薪
A8: =COUNTA(A$4:A7)+1 -> 5 | B8: 平井進
B9: 長谷川聡
A10: =COUNTA(A$4:A9)+1 -> 6 | B10: 粟飯原功
A11: =COUNTA(A$4:A10)+1 -> 7 | B11: 高橋正
A12: =COUNTA(A$4:A11)+1 -> 8 | B12: 林信行 | E12: =A12 -> 8
B13: １区２班
A14: 評議員： 齋藤勇 | C14: 返礼チェック
A15: No. | B15: =$B$3 -> 奉納者 | C15: ☑
A16: 1 | B16: 紺野建設
A17: =COUNTA(A$16:A16)+1 -> 2 | B17: 遠山美代子
A18: =COUNTA(A$16:A17)+1 -> 3 | B18: 高瀬一
A19: =COUNTA(A$16:A18)+1 -> 4 | B19: 齋藤勇
A20: =COUNTA(A$16:A19)+1 -> 5 | B20: 鍋田益男
B21: マミークリーニング
A22: =COUNTA(A$16:A21)+1 -> 6 | B22: 佐藤清
A23: =COUNTA(A$16:A22)+1 -> 7 | B23: 戸村則登 | E23: =A23 -> 7
B24: １区３班
A25: 評議員： 佐久間明 | C25: 返礼チェック
A26: No. | B26: =$B$3 -> 奉納者 | C26: ☑
A27: 1 | B27: 佐久間明
A28: =COUNTA(A$27:A27)+1 -> 2 | B28: 鳥居スミヱ
A29: =COUNTA(A$27:A28)+1 -> 3 | B29: 渋江康弘
A30: =COUNTA(A$27:A29)+1 -> 4 | B30: 石岡明憲
A31: =COUNTA(A$27:A30)+1 -> 5 | B31: 中華料理成都
A32: =COUNTA(A$27:A31)+1 -> 6 | B32: 武藤親弘
A33: =COUNTA(A$27:A32)+1 -> 7 | B33: 串一
A34: =COUNTA(A$27:A33)+1 -> 8 | B34: ｱｼﾞﾄ中村みどり | E34: =A34 -> 8
B35: １区４班
A36: 評議員： 秋山芳美 | C36: 返礼チェック
A37: No. | B37: =$B$3 -> 奉納者 | C37: ☑
A38: 1 | B38: 澤登武文
A39: =COUNTA(A$38:A38)+1 -> 2 | B39: 秋山芳美
A40: =COUNTA(A$38:A39)+1 -> 3 | B40: 櫻井治
...

Sheet ⑪寄付者一覧 (金額別）
