Workbook

Sheet Sheet1
B2: =マスタ!F3 -> 中村芳朗
B3: =マスタ!F4 -> 中村治子
B4: =マスタ!F5 -> 松川正士
B5: =マスタ!F6 -> 和田薪
B6: =マスタ!F7 -> 平井進
B7: =マスタ!F8 -> 長谷川聰
B8: =マスタ!F9 -> 粟飯原功
B9: =マスタ!F10 -> 高橋正
B10: =マスタ!F11 -> 林信行
B11: =マスタ!F12 -> 町田恵資
B12: =マスタ!F13 -> 紺野建設
B13: =マスタ!F14 -> 遠山悦子
... B213: =マスタ!F214 -> 0

Sheet マスタ
A1: 駒寄町内会 会員名簿 (2026年06月02日現在) | J1: 避難 支援 | K1: 同居 家族
A2: 通番 | B2: 区 | C2: 班 | D2: No. | E2: 評議員 | F2: 氏名 ／ 屋号 | G2: 住所番地 | H2: 電 話 | I2: 備 考
A3: =ROW()-2 -> 1 | B3: 1 | C3: 1 | D3: =IF(AND(B2=B3,C2=C3),D2+1,1) -> 1 | F3: 中村芳朗 | G3: 6－1 | H3: 861－2770 | I3: 芳朗ﾖｼﾛｳ R8.2月(75) | J3: 要 | K3: 2
A4: =ROW()-2 -> 2 | B4: 1 | C4: 1 | D4: =IF(AND(B3=B4,C3=C4),D3+1,1) -> 2 | F4: 中村治子 | G4: 6－1 | H4: 861－2446 | I4: 治子ﾊﾙｺ R8.2月(81)S19.8.24 | J4: 不要 | K4: 0
A5: =ROW()-2 -> 3 | B5: 1 | C5: 1 | D5: =IF(AND(B4=B5,C4=C5),D4+1,1) -> 3 | F5: 松川正士 | G5: 6－1 | H5: 090-1779-5352 | I5: 正士ﾏｻｼ R8.2月(81)S19.3.31, 真美,妃由 | J5: 不要 | K5: 3 | L5: 861－2384
A6: =ROW()-2 -> 4 | B6: 1 | C6: 1 | D6: =IF(AND(B5=B6,C5=C6),D5+1,1) -> 4 | F6: 和田薪 | G6: 6－1 | H6: 861－2481 | I6: セラヴィ 京子R7(79)S21.7.5 | J6: 不要
A7: =ROW()-2 -> 5 | B7: 1 | C7: 1 | D7: =IF(AND(B6=B7,C6=C7),D6+1,1) -> 5 | F7: 平井進 | G7: 6－2 | H7: 861－3291 | I7: 進 R8.2月(78)S23.2.23 | J7: 不要 | K7: 0
A8: =ROW()-2 -> 6 | B8: 1 | C8: 1 | D8: =IF(AND(B7=B8,C7=C8),D7+1,1) -> 6 | F8: 長谷川聰 | G8: 6－2 | I8: H29.4～ 聰ｻﾄｼ S17.11.16(84) | J8: 不要 | K8: 0
A9: =ROW()-2 -> 7 | B9: 1 | C9: 1 | D9: =IF(AND(B8=B9,C8=C9),D8+1,1) -> 7 | F9: 粟飯原功 | G9: 6－2 | H9: 861－4015 | I9: R7(78)S23.1.19 | J9: 不要 | K9: 0
A10: =ROW()-2 -> 8 | B10: 1 | C10: 1 | D10: =IF(AND(B9=B10,C9=C10),D9+1,1) -> 8 | E10: ● | F10: 高橋正 | G10: 6－2 | H10: 861－0178 | I10: 正(R8.2月 62才)R3.評議員は「しのぶ」さん | J10: 不要 | K10: 2
A11: =ROW()-2 -> 9 | B11: 1 | C11: 1 | D11: =IF(AND(B10=B11,C10=C11),D10+1,1) -> 9 | F11: 林信行 | G11: 6－2 | H11: 090-3916-4588 | I11: H29.4(79)～ 046-854-9786 同居佐藤たい子R7(93)S6.11.6 | J11: 要 | K11: 2
A12: =ROW()-2 -> 10 | B12: 1 | C12: 1 | D12: =IF(AND(B11=B12,C11=C12),D11+1,1) -> 10 | F12: 町田恵資 | G12: 6－1 | H12: 046-861-1644 | I12: S44.5.26生 ※行事は不参加
A13: =ROW()-2 -> 11 | B13: 1 | C13: 2 | D13: =IF(AND(B11=B13,C11=C13),D11+1,1) -> 1 | F13: 紺野建設 | G13: 6－69 | H13: 861－3180 | J13: 不要
A14: =ROW()-2 -> 12 | B14: 1 | C14: 2 | D14: =IF(AND(B13=B14,C13=C14),D13+1,1) -> 2 | F14: 遠山悦子 | G14: 6－68 | H14: 861－3815 | I14: 悦子(r8.1月 60) R5.美代子さん逝去 | J14: 不要 | K14: 0
A15: =ROW()-2 -> 13 | B15: 1 | C15: 2 | D15: =IF(AND(B14=B15,C14=C15),D14+1,1) -> 3 | F15: 高瀬一 | G15: 6－69 | H15: 861－0509 | I15: 一ﾊｼﾞﾒR7(77)S23.9.22、幸子(80)S20.7.11、徹(?) | J15: 要 | K15: 6
A16: =ROW()-2 -> 14 | B16: 1 | C16: 2 | D16: =IF(AND(B15=B16,C15=C16),D15+1,1) -> 4 | F16: 齋藤勇 | G16: 6－68 | H16: 861－3823 | I16: 勇R8.2月(79)S21.8.4、ヨシ子(93)S6.1.2 | J16: 不要 | K16: 1
A17: =ROW()-2 -> 15 | B17: 1 | C17: 2 | D17: =IF(AND(B16=B17,C16=C17),D16+1,1) -> 5 | F17: 鍋田益男 | G17: 6－68片山303 | H17: 861－5959 | I17: 益男(88)S11.1.24、久枝(86)S14.2.16
A18: =ROW()-2 -> 16 | B18: 1 | C18: 2 | D18: =IF(AND(B17=B18,C17=C18),D17+1,1) -> 6 | F18: マミークリーニング | G18: 6－68 | H18: 861－1220
A19: =ROW()-2 -> 17 | B19: 1 | C19: 2 | D19: =IF(AND(B18=B19,C18=C19),D18+1,1) -> 7 | F19: 佐藤清 | G19: 6－69 | H19: 861－6235 | I19: H29.4～ 佐藤歯科（夜間不在） | J19: 不要 | K19: 0
A20: =ROW()-2 -> 18 | B20: 1 | C20: 2 | D20: =IF(AND(B19=B20,C19=C20),D19+1,1) -> 8 | E20: ● | F20: 戸村則登 | G20: 6－68-19 | H20: 090-6346-9518 | I20: R7.6月加入、S33.7.29生(67) | J20: 不要 | K20: 3
A21: =ROW()-2 -> 19 | B21: 1 | C21: 2 | D21: =IF(AND(B20=B21,C20=C21),D20+1,1) -> 9 | F21: 渡邊秀一 | G21: 6-69-12 | H21: 090-9328-7011 | I21: S62.5.30生(38) | J21: 不要 | K21: 1
A22: =ROW()-2 -> 20 | B22: 1 | C22: 3 | D22: =IF(AND(B19=B22,C19=C22),D19+1,1) -> 1 | F22: 佐久間明 | G22: 6－69 | H22: 861－3753 | I22: 明R8.2月(75)、満貴子ﾏｷｺ(?),均(090-9305-5987)梢(080-5078-6336),光,匠,楓 | J22: 不要 | K22: 7
A23: =ROW()-2 -> 21 | B23: 1 | C23: 3 | D23: =IF(AND(B22=B23,C22=C23),D22+1,1) -> 2 | F23: 鳥居スミヱ | G23: 6－77 | H23: 861－4993 | I23: 評議員は鳥居知加代 スミヱ(93)S7.5.31 | J23: 要 | K23: 1
A24: =ROW()-2 -> 22 | B24: 1 | C24: 3 | D24: =IF(AND(B23=B24,C23=C24),D23+1,1) -> 3 | F24: 渋江康弘 | G24: 6－77 | H24: 897－7032 | I24: 康弘ﾔｽﾋﾛR8.2月(82)S18.8.18、秀子ﾋﾃﾞｺ(79)S22.1.22 | J24: 不要 | K24: 1
A25: =ROW()-2 -> 23 | B25: 1 | C25: 3 | D25: =IF(AND(B24=B25,C24=C25),D24+1,1) -> 4 | E25: ● | F25: 石岡明憲 | G25: 6－77 | H25: 861－0925 | I25: (r8.1月 59) | J25: 不要 | K25: 1
A26: =ROW()-2 -> 24 | B26: 1 | C26: 3 | D26: =IF(AND(B25=B26,C25=C26),D25+1,1) -> 5 | F26: 中華料理成都 | G26: 6－77 | H26: 861－8060 | I26: 松本秀雄R8.2月(56) | J26: 不要 | K26: 1
A27: =ROW()-2 -> 25 | B27: 1 | C27: 3 | D27: =IF(AND(B26=B27,C26=C27),D26+1,1) -> 6 | F27: 武藤親弘 | G27: 6－76-4 | H27: 861－5829 | I27: 慎一R7(78)S22.4.25 親弘(R8.2月45歳, 090-7225-8149)敏恵,慎太郎,光次郎 | J27: 不要 | K27: 4
A28: =ROW()-2 -> 26 | B28: 1 | C28: 3 | D28: =IF(AND(B27=B28,C27=C28),D27+1,1) -> 7 | F28: 串一 | G28: 6－77 | H28: 861－2733 | I28: 中村太一 店舗 | J28: 不要
A29: =ROW()-2 -> 27 | B29: 1 | C29: 3 | D29: =IF(AND(B28=B29,C28=C29),D28+1,1) -> 8 | F29: AJITO中村みどり | G29: 6－77 | H29: 887－0676 | I29: 中村修一R8.2月(77)S23.10.15 店舗 | J29: 不要 | K29: 2
A30: =ROW()-2 -> 28 | B30: 1 | C30: 4 | D30: =IF(AND(B29=B30,C29=C30),D29+1,1) -> 1 | E30: ● | F30: 澤登武文 | G30: 6－75 | H30: 861－4214 | I30: 武文(R8.2月 56)R4 弘志さん逝去 | J30: 不要 | K30: 2
A31: =ROW()-2 -> 29 | B31: 1 | C31: 4 | D31: =IF(AND(B30=B31,C30=C31),D30+1,1) -> 2 | F31: 秋山芳美 | G31: 6－74 | H31: 861－7234 | I31: 芳美(R8.2月 57) | J31: 不要 | K31: 4
A32: =ROW()-2 -> 30 | B32: 1 | C32: 4 | D32: =IF(AND(B31=B32,C31=C32),D31+1,1) -> 3 | F32: 櫻井治 | G32: 6－74 | H32: 861－2490 | I32: 治ｵｻﾑR7(76)S24.2.2・美保子ﾐﾎｺ(76)S24.11.4 | J32: 不要 | K32: 3
A33: =ROW()-2 -> 31 | B33: 1 | C33: 4 | D33: =IF(AND(B32=B33,C32=C33),D32+1,1) -> 4 | F33: 松永彰 | G33: 6－74 | H33: 861－2132 | I33: プレミール 彰ｱｷﾗR7(75)、正子(?) | J33: 不要 | K33: 1
A34: =ROW()-2 -> 32 | B34: 1 | C34: 4 | D34: =IF(AND(B33=B34,C33=C34),D33+1,1) -> 5 | F34: 橋本勇 | G34: 6－74 | H34: 861－2905 | I34: 勇ｲｻﾑR7(80)S20.5.18・愛子(79)S21.8.9 | J34: 不要 | K34: 3
A35: =ROW()-2 -> 33 | B35: 1 | C35: 4 | D35: =IF(AND(B34=B35,C34=C35),D34+1,1) -> 6 | F35: 瀧下なつみ | G35: 6－75 | H35: 080-5417-6576 | I35: なつみ(R8.2月 30) R1.4〜スズサンマンション302, 礼 | J35: 不要 | K35: 2
A36: =ROW()-2 -> 34 | B36: 1 | C36: 5 | D36: =IF(AND(B35=B36,C35=C36),D35+1,1) -> 1 | F36: 鈴木洋一 | G36: 6－66－４ G3 | H36: 090-8506-2232 | I36: 102号室 洋一(R8.2月55歳)（861-8656 or 4686）評議員は宣子,理沙,玲奈 | J36: 不要 | K36: 5
A37: =ROW()-2 -> 35 | B37: 1 | C37: 5 | D37: =IF(AND(B36=B37,C36=C37),D36+1,1) -> 2 | E37: ● | F37: 首藤睦 | G37: 6－66－４ G3 | H37: 861－9056 | I37: 203号室 睦(R8.2月56歳) | J37: 不要 | K37: 1
A38: =ROW()-2 -> 36 | B38: 1 | C38: 5 | D38: =IF(AND(B37=B38,C37=C38),D37+1,1) -> 3 | F38: 大野誠治 | G38: 6－66－４ G3 | H38: 861－8652 | I38: 403号室 誠治(R8.2月 61歳), 優李亜 | J38: 不要 | K38: 1
A39: =ROW()-2 -> 37 | B39: 1 | C39: 6 | D39: =IF(AND(B38=B39,C38=C39),D38+1,1) -> 1 | F39: 青山啓二 | G39: 6－66 | H39: 861－3697 | I39: 啓二(R8.2月 73歳), 順子ｼﾞｭﾝｺR7(75) | J39: 不要 | K39: 2
A40: =ROW()-2 -> 38 | B40: 1 | C40: 6 | D40: =IF(AND(B39=B40,C39=C40),D39+1,1) -> 2 | F40: 西田善隆 | G40: 6－70 | H40: 861－6352 | I40: 善隆R8.2月(54) | J40: 不要 | K40: 1
...

Sheet 2026-0602
A1: 駒寄町内会 会員名簿 (2026年06月02日現在) | J1: 避難 支援 | K1: 同居 家族
A2: 通番 | B2: 区 | C2: 班 | D2: No. | E2: 評議員 | F2: 氏名 ／ 屋号 | G2: 住所番地 | H2: 電 話 | I2: 備 考
A3: =ROW()-2 -> 1 | B3: 1 | C3: 1 | D3: =IF(AND(B2=B3,C2=C3),D2+1,1) -> 1 | F3: 中村芳朗 | G3: 6－1 | H3: 861－2770 | I3: 芳朗ﾖｼﾛｳ R8.2月(75) | J3: 要 | K3: 2
A4: =ROW()-2 -> 2 | B4: 1 | C4: 1 | D4: =IF(AND(B3=B4,C3=C4),D3+1,1) -> 2 | F4: 中村治子 | G4: 6－1 | H4: 861－2446 | I4: 治子ﾊﾙｺ R8.2月(81)S19.8.24 | J4: 不要 | K4: 0
A5: =ROW()-2 -> 3 | B5: 1 | C5: 1 | D5: =IF(AND(B4=B5,C4=C5),D4+1,1) -> 3 | F5: 松川正士 | G5: 6－1 | H5: 090-1779-5352 | I5: 正士ﾏｻｼ R8.2月(81)S19.3.31, 真美,妃由 | J5: 不要 | K5: 3 | L5: 861－2384
A6: =ROW()-2 -> 4 | B6: 1 | C6: 1 | D6: =IF(AND(B5=B6,C5=C6),D5+1,1) -> 4 | F6: 和田薪 | G6: 6－1 | H6: 861－2481 | I6: セラヴィ 京子R7(79)S21.7.5 | J6: 不要
A7: =ROW()-2 -> 5 | B7: 1 | C7: 1 | D7: =IF(AND(B6=B7,C6=C7),D6+1,1) -> 5 | F7: 平井進 | G7: 6－2 | H7: 861－3291 | I7: 進 R8.2月(78)S23.2.23 | J7: 不要 | K7: 0
A8: =ROW()-2 -> 6 | B8: 1 | C8: 1 | D8: =IF(AND(B7=B8,C7=C8),D7+1,1) -> 6 | F8: 長谷川聰 | G8: 6－2 | I8: H29.4～ 聰ｻﾄｼ S17.11.16(84) | J8: 不要 | K8: 0
A9: =ROW()-2 -> 7 | B9: 1 | C9: 1 | D9: =IF(AND(B8=B9,C8=C9),D8+1,1) -> 7 | F9: 粟飯原功 | G9: 6－2 | H9: 861－4015 | I9: R7(78)S23.1.19 | J9: 不要 | K9: 0
A10: =ROW()-2 -> 8 | B10: 1 | C10: 1 | D10: =IF(AND(B9=B10,C9=C10),D9+1,1) -> 8 | E10: ● | F10: 高橋正 | G10: 6－2 | H10: 861－0178 | I10: 正(R8.2月 62才)R3.評議員は「しのぶ」さん | J10: 不要 | K10: 2
A11: =ROW()-2 -> 9 | B11: 1 | C11: 1 | D11: =IF(AND(B10=B11,C10=C11),D10+1,1) -> 9 | F11: 林信行 | G11: 6－2 | H11: 090-3916-4588 | I11: H29.4(79)～ 046-854-9786 同居佐藤たい子R7(93)S6.11.6 | J11: 要 | K11: 2
A12: =ROW()-2 -> 10 | B12: 1 | C12: 1 | D12: =IF(AND(B11=B12,C11=C12),D11+1,1) -> 10 | F12: 町田恵資 | G12: 6－1 | H12: 046-861-1644 | I12: S44.5.26生 ※行事は不参加
A13: =ROW()-2 -> 11 | B13: 1 | C13: 2 | D13: =IF(AND(B11=B13,C11=C13),D11+1,1) -> 1 | F13: 紺野建設 | G13: 6－69 | H13: 861－3180 | J13: 不要
A14: =ROW()-2 -> 12 | B14: 1 | C14: 2 | D14: =IF(AND(B13=B14,C13=C14),D13+1,1) -> 2 | F14: 遠山悦子 | G14: 6－68 | H14: 861－3815 | I14: 悦子(r8.1月 60) R5.美代子さん逝去 | J14: 不要 | K14: 0
A15: =ROW()-2 -> 13 | B15: 1 | C15: 2 | D15: =IF(AND(B14=B15,C14=C15),D14+1,1) -> 3 | F15: 高瀬一 | G15: 6－69 | H15: 861－0509 | I15: 一ﾊｼﾞﾒR7(77)S23.9.22、幸子(80)S20.7.11、徹(?) | J15: 要 | K15: 6
A16: =ROW()-2 -> 14 | B16: 1 | C16: 2 | D16: =IF(AND(B15=B16,C15=C16),D15+1,1) -> 4 | F16: 齋藤勇 | G16: 6－68 | H16: 861－3823 | I16: 勇R8.2月(79)S21.8.4、ヨシ子(93)S6.1.2 | J16: 不要 | K16: 1
A17: =ROW()-2 -> 15 | B17: 1 | C17: 2 | D17: =IF(AND(B16=B17,C16=C17),D16+1,1) -> 5 | F17: 鍋田益男 | G17: 6－68片山303 | H17: 861－5959 | I17: 益男(88)S11.1.24、久枝(86)S14.2.16
A18: =ROW()-2 -> 16 | B18: 1 | C18: 2 | D18: =IF(AND(B17=B18,C17=C18),D17+1,1) -> 6 | F18: マミークリーニング | G18: 6－68 | H18: 861－1220
A19: =ROW()-2 -> 17 | B19: 1 | C19: 2 | D19: =IF(AND(B18=B19,C18=C19),D18+1,1) -> 7 | F19: 佐藤清 | G19: 6－69 | H19: 861－6235 | I19: H29.4～ 佐藤歯科（夜間不在） | J19: 不要 | K19: 0
A20: =ROW()-2 -> 18 | B20: 1 | C20: 2 | D20: =IF(AND(B19=B20,C19=C20),D19+1,1) -> 8 | E20: ● | F20: 戸村則登 | G20: 6－68-19 | H20: 090-6346-9518 | I20: R7.6月加入、S33.7.29生(67) | J20: 不要 | K20: 3
A21: =ROW()-2 -> 19 | B21: 1 | C21: 2 | D21: =IF(AND(B20=B21,C20=C21),D20+1,1) -> 9 | F21: 渡邊秀一 | G21: 6-69-12 | H21: 090-9328-7011 | I21: S62.5.30生(38) | J21: 不要 | K21: 1
A22: =ROW()-2 -> 20 | B22: 1 | C22: 3 | D22: =IF(AND(B19=B22,C19=C22),D19+1,1) -> 1 | F22: 佐久間明 | G22: 6－69 | H22: 861－3753 | I22: 明R8.2月(75)、満貴子ﾏｷｺ(?),均(090-9305-5987)梢(080-5078-6336),光,匠,楓 | J22: 不要 | K22: 7
A23: =ROW()-2 -> 21 | B23: 1 | C23: 3 | D23: =IF(AND(B22=B23,C22=C23),D22+1,1) -> 2 | F23: 鳥居スミヱ | G23: 6－77 | H23: 861－4993 | I23: 評議員は鳥居知加代 スミヱ(93)S7.5.31 | J23: 要 | K23: 1
A24: =ROW()-2 -> 22 | B24: 1 | C24: 3 | D24: =IF(AND(B23=B24,C23=C24),D23+1,1) -> 3 | F24: 渋江康弘 | G24: 6－77 | H24: 897－7032 | I24: 康弘ﾔｽﾋﾛR8.2月(82)S18.8.18、秀子ﾋﾃﾞｺ(79)S22.1.22 | J24: 不要 | K24: 1
A25: =ROW()-2 -> 23 | B25: 1 | C25: 3 | D25: =IF(AND(B24=B25,C24=C25),D24+1,1) -> 4 | E25: ● | F25: 石岡明憲 | G25: 6－77 | H25: 861－0925 | I25: (r8.1月 59) | J25: 不要 | K25: 1
A26: =ROW()-2 -> 24 | B26: 1 | C26: 3 | D26: =IF(AND(B25=B26,C25=C26),D25+1,1) -> 5 | F26: 中華料理成都 | G26: 6－77 | H26: 861－8060 | I26: 松本秀雄R8.2月(56) | J26: 不要 | K26: 1
A27: =ROW()-2 -> 25 | B27: 1 | C27: 3 | D27: =IF(AND(B26=B27,C26=C27),D26+1,1) -> 6 | F27: 武藤親弘 | G27: 6－76-4 | H27: 861－5829 | I27: 慎一R7(78)S22.4.25 親弘(R8.2月45歳, 090-7225-8149)敏恵,慎太郎,光次郎 | J27: 不要 | K27: 4
A28: =ROW()-2 -> 26 | B28: 1 | C28: 3 | D28: =IF(AND(B27=B28,C27=C28),D27+1,1) -> 7 | F28: 串一 | G28: 6－77 | H28: 861－2733 | I28: 中村太一 店舗 | J28: 不要
A29: =ROW()-2 -> 27 | B29: 1 | C29: 3 | D29: =IF(AND(B28=B29,C28=C29),D28+1,1) -> 8 | F29: AJITO中村みどり | G29: 6－77 | H29: 887－0676 | I29: 中村修一R8.2月(77)S23.10.15 店舗 | J29: 不要 | K29: 2
A30: =ROW()-2 -> 28 | B30: 1 | C30: 4 | D30: =IF(AND(B29=B30,C29=C30),D29+1,1) -> 1 | E30: ● | F30: 澤登武文 | G30: 6－75 | H30: 861－4214 | I30: 武文(R8.2月 56)R4 弘志さん逝去 | J30: 不要 | K30: 2
A31: =ROW()-2 -> 29 | B31: 1 | C31: 4 | D31: =IF(AND(B30=B31,C30=C31),D30+1,1) -> 2 | F31: 秋山芳美 | G31: 6－74 | H31: 861－7234 | I31: 芳美(R8.2月 57) | J31: 不要 | K31: 4
A32: =ROW()-2 -> 30 | B32: 1 | C32: 4 | D32: =IF(AND(B31=B32,C31=C32),D31+1,1) -> 3 | F32: 櫻井治 | G32: 6－74 | H32: 861－2490 | I32: 治ｵｻﾑR7(76)S24.2.2・美保子ﾐﾎｺ(76)S24.11.4 | J32: 不要 | K32: 3
A33: =ROW()-2 -> 31 | B33: 1 | C33: 4 | D33: =IF(AND(B32=B33,C32=C33),D32+1,1) -> 4 | F33: 松永彰 | G33: 6－74 | H33: 861－2132 | I33: プレミール 彰ｱｷﾗR7(75)、正子(?) | J33: 不要 | K33: 1
A34: =ROW()-2 -> 32 | B34: 1 | C34: 4 | D34: =IF(AND(B33=B34,C33=C34),D33+1,1) -> 5 | F34: 橋本勇 | G34: 6－74 | H34: 861－2905 | I34: 勇ｲｻﾑR7(80)S20.5.18・愛子(79)S21.8.9 | J34: 不要 | K34: 3
A35: =ROW()-2 -> 33 | B35: 1 | C35: 4 | D35: =IF(AND(B34=B35,C34=C35),D34+1,1) -> 6 | F35: 瀧下なつみ | G35: 6－75 | H35: 080-5417-6576 | I35: なつみ(R8.2月 30) R1.4〜スズサンマンション302, 礼 | J35: 不要 | K35: 2
A36: =ROW()-2 -> 34 | B36: 1 | C36: 5 | D36: =IF(AND(B35=B36,C35=C36),D35+1,1) -> 1 | F36: 鈴木洋一 | G36: 6－66－４ G3 | H36: 090-8506-2232 | I36: 102号室 洋一(R8.2月55歳)（861-8656 or 4686）評議員は宣子,理沙,玲奈 | J36: 不要 | K36: 5
A37: =ROW()-2 -> 35 | B37: 1 | C37: 5 | D37: =IF(AND(B36=B37,C36=C37),D36+1,1) -> 2 | E37: ● | F37: 首藤睦 | G37: 6－66－４ G3 | H37: 861－9056 | I37: 203号室 睦(R8.2月56歳) | J37: 不要 | K37: 1
A38: =ROW()-2 -> 36 | B38: 1 | C38: 5 | D38: =IF(AND(B37=B38,C37=C38),D37+1,1) -> 3 | F38: 大野誠治 | G38: 6－66－４ G3 | H38: 861－8652 | I38: 403号室 誠治(R8.2月 61歳), 優李亜 | J38: 不要 | K38: 1
A39: =ROW()-2 -> 37 | B39: 1 | C39: 6 | D39: =IF(AND(B38=B39,C38=C39),D38+1,1) -> 1 | F39: 青山啓二 | G39: 6－66 | H39: 861－3697 | I39: 啓二(R8.2月 73歳), 順子ｼﾞｭﾝｺR7(75) | J39: 不要 | K39: 2
A40: =ROW()-2 -> 38 | B40: 1 | C40: 6 | D40: =IF(AND(B39=B40,C39=C40),D39+1,1) -> 2 | F40: 西田善隆 | G40: 6－70 | H40: 861－6352 | I40: 善隆R8.2月(54) | J40: 不要 | K40: 1
...

Sheet 2026-0524
A1: 駒寄町内会 会員名簿 (2026年05月24日現在) | J1: 避難 支援 | K1: 同居 家族
A2: 通番 | B2: 区 | C2: 班 | D2: No. | E2: 評議員 | F2: 氏名 ／ 屋号 | G2: 住所番地 | H2: 電 話 | I2: 備 考
A3: =ROW()-2 -> 1 | B3: 1 | C3: 1 | D3: =IF(AND(B2=B3,C2=C3),D2+1,1) -> 1 | F3: 中村芳朗 | G3: 6－1 | H3: 861－2770 | I3: 芳朗ﾖｼﾛｳ R8.2月(75) | J3: 要 | K3: 2
A4: =ROW()-2 -> 2 | B4: 1 | C4: 1 | D4: =IF(AND(B3=B4,C3=C4),D3+1,1) -> 2 | F4: 中村治子 | G4: 6－1 | H4: 861－2446 | I4: 治子ﾊﾙｺ R8.2月(81)S19.8.24 | J4: 不要 | K4: 0
A5: =ROW()-2 -> 3 | B5: 1 | C5: 1 | D5: =IF(AND(B4=B5,C4=C5),D4+1,1) -> 3 | F5: 松川正士 | G5: 6－1 | H5: 090-1779-5352 | I5: 正士ﾏｻｼ R8.2月(81)S19.3.31, 真美,妃由 | J5: 不要 | K5: 3 | L5: 861－2384
A6: =ROW()-2 -> 4 | B6: 1 | C6: 1 | D6: =IF(AND(B5=B6,C5=C6),D5+1,1) -> 4 | F6: 和田薪 | G6: 6－1 | H6: 861－2481 | I6: セラヴィ 京子R7(79)S21.7.5 | J6: 不要
A7: =ROW()-2 -> 5 | B7: 1 | C7: 1 | D7: =IF(AND(B6=B7,C6=C7),D6+1,1) -> 5 | F7: 平井進 | G7: 6－2 | H7: 861－3291 | I7: 進 R8.2月(78)S23.2.23 | J7: 不要 | K7: 0
A8: =ROW()-2 -> 6 | B8: 1 | C8: 1 | D8: =IF(AND(B7=B8,C7=C8),D7+1,1) -> 6 | F8: 長谷川聰 | G8: 6－2 | I8: H29.4～ 聰ｻﾄｼ S17.11.16(84) | J8: 不要 | K8: 0
A9: =ROW()-2 -> 7 | B9: 1 | C9: 1 | D9: =IF(AND(B8=B9,C8=C9),D8+1,1) -> 7 | F9: 粟飯原功 | G9: 6－2 | H9: 861－4015 | I9: R7(78)S23.1.19 | J9: 不要 | K9: 0
A10: =ROW()-2 -> 8 | B10: 1 | C10: 1 | D10: =IF(AND(B9=B10,C9=C10),D9+1,1) -> 8 | E10: ● | F10: 高橋正 | G10: 6－2 | H10: 861－0178 | I10: 正(R8.2月 62才)R3.評議員は「しのぶ」さん | J10: 不要 | K10: 2
A11: =ROW()-2 -> 9 | B11: 1 | C11: 1 | D11: =IF(AND(B10=B11,C10=C11),D10+1,1) -> 9 | F11: 林信行 | G11: 6－2 | H11: 090-3916-4588 | I11: H29.4(79)～ 046-854-9786 同居佐藤たい子R7(93)S6.11.6 | J11: 要 | K11: 2
A12: =ROW()-2 -> 10 | B12: 1 | C12: 1 | D12: =IF(AND(B11=B12,C11=C12),D11+1,1) -> 10 | F12: 町田恵資 | G12: 6－1 | H12: 046-861-1644 | I12: S44.5.26生 ※行事は不参加
A13: =ROW()-2 -> 11 | B13: 1 | C13: 2 | D13: =IF(AND(B11=B13,C11=C13),D11+1,1) -> 1 | F13: 紺野建設 | G13: 6－69 | H13: 861－3180 | J13: 不要
A14: =ROW()-2 -> 12 | B14: 1 | C14: 2 | D14: =IF(AND(B13=B14,C13=C14),D13+1,1) -> 2 | F14: 遠山悦子 | G14: 6－68 | H14: 861－3815 | I14: 悦子(r8.1月 60) R5.美代子さん逝去 | J14: 不要 | K14: 0
A15: =ROW()-2 -> 13 | B15: 1 | C15: 2 | D15: =IF(AND(B14=B15,C14=C15),D14+1,1) -> 3 | F15: 高瀬一 | G15: 6－69 | H15: 861－0509 | I15: 一ﾊｼﾞﾒR7(77)S23.9.22、幸子(80)S20.7.11、徹(?) | J15: 要 | K15: 6
A16: =ROW()-2 -> 14 | B16: 1 | C16: 2 | D16: =IF(AND(B15=B16,C15=C16),D15+1,1) -> 4 | F16: 齋藤勇 | G16: 6－68 | H16: 861－3823 | I16: 勇R8.2月(79)S21.8.4、ヨシ子(93)S6.1.2 | J16: 不要 | K16: 1
A17: =ROW()-2 -> 15 | B17: 1 | C17: 2 | D17: =IF(AND(B16=B17,C16=C17),D16+1,1) -> 5 | F17: 鍋田益男 | G17: 6－68片山303 | H17: 861－5959 | I17: 益男(88)S11.1.24、久枝(86)S14.2.16
A18: =ROW()-2 -> 16 | B18: 1 | C18: 2 | D18: =IF(AND(B17=B18,C17=C18),D17+1,1) -> 6 | F18: マミークリーニング | G18: 6－68 | H18: 861－1220
A19: =ROW()-2 -> 17 | B19: 1 | C19: 2 | D19: =IF(AND(B18=B19,C18=C19),D18+1,1) -> 7 | F19: 佐藤清 | G19: 6－69 | H19: 861－6235 | I19: H29.4～ 佐藤歯科（夜間不在） | J19: 不要 | K19: 0
A20: =ROW()-2 -> 18 | B20: 1 | C20: 2 | D20: =IF(AND(B19=B20,C19=C20),D19+1,1) -> 8 | E20: ● | F20: 戸村則登 | G20: 6－68-19 | H20: 090-6346-9518 | I20: R7.6月加入、S33.7.29生(67) | J20: 不要 | K20: 3
A21: =ROW()-2 -> 19 | B21: 1 | C21: 2 | D21: =IF(AND(B20=B21,C20=C21),D20+1,1) -> 9 | F21: 渡邊秀一 | G21: 6-69-12 | H21: 090-9328-7011 | I21: S62.5.30生(38) | J21: 不要 | K21: 1
A22: =ROW()-2 -> 20 | B22: 1 | C22: 3 | D22: =IF(AND(B19=B22,C19=C22),D19+1,1) -> 1 | F22: 佐久間明 | G22: 6－69 | H22: 861－3753 | I22: 明R8.2月(75)、満貴子ﾏｷｺ(?),均(090-9305-5987)梢(080-5078-6336),光,匠,楓 | J22: 不要 | K22: 7
A23: =ROW()-2 -> 21 | B23: 1 | C23: 3 | D23: =IF(AND(B22=B23,C22=C23),D22+1,1) -> 2 | F23: 鳥居スミヱ | G23: 6－77 | H23: 861－4993 | I23: 評議員は鳥居知加代 スミヱ(93)S7.5.31 | J23: 要 | K23: 1
A24: =ROW()-2 -> 22 | B24: 1 | C24: 3 | D24: =IF(AND(B23=B24,C23=C24),D23+1,1) -> 3 | F24: 渋江康弘 | G24: 6－77 | H24: 897－7032 | I24: 康弘ﾔｽﾋﾛR8.2月(82)S18.8.18、秀子ﾋﾃﾞｺ(79)S22.1.22 | J24: 不要 | K24: 1
A25: =ROW()-2 -> 23 | B25: 1 | C25: 3 | D25: =IF(AND(B24=B25,C24=C25),D24+1,1) -> 4 | E25: ● | F25: 石岡明憲 | G25: 6－77 | H25: 861－0925 | I25: (r8.1月 59) | J25: 不要 | K25: 1
A26: =ROW()-2 -> 24 | B26: 1 | C26: 3 | D26: =IF(AND(B25=B26,C25=C26),D25+1,1) -> 5 | F26: 中華料理成都 | G26: 6－77 | H26: 861－8060 | I26: 松本秀雄R8.2月(56) | J26: 不要 | K26: 1
A27: =ROW()-2 -> 25 | B27: 1 | C27: 3 | D27: =IF(AND(B26=B27,C26=C27),D26+1,1) -> 6 | F27: 武藤親弘 | G27: 6－76-4 | H27: 861－5829 | I27: 慎一R7(78)S22.4.25 親弘(R8.2月45歳, 090-7225-8149)敏恵,慎太郎,光次郎 | J27: 不要 | K27: 4
A28: =ROW()-2 -> 26 | B28: 1 | C28: 3 | D28: =IF(AND(B27=B28,C27=C28),D27+1,1) -> 7 | F28: 串一 | G28: 6－77 | H28: 861－2733 | I28: 中村太一 店舗 | J28: 不要
A29: =ROW()-2 -> 27 | B29: 1 | C29: 3 | D29: =IF(AND(B28=B29,C28=C29),D28+1,1) -> 8 | F29: AJITO中村みどり | G29: 6－77 | H29: 887－0676 | I29: 中村修一R8.2月(77)S23.10.15 店舗 | J29: 不要 | K29: 2
A30: =ROW()-2 -> 28 | B30: 1 | C30: 4 | D30: =IF(AND(B29=B30,C29=C30),D29+1,1) -> 1 | E30: ● | F30: 澤登武文 | G30: 6－75 | H30: 861－4214 | I30: 武文(R8.2月 56)R4 弘志さん逝去 | J30: 不要 | K30: 2
A31: =ROW()-2 -> 29 | B31: 1 | C31: 4 | D31: =IF(AND(B30=B31,C30=C31),D30+1,1) -> 2 | F31: 秋山芳美 | G31: 6－74 | H31: 861－7234 | I31: 芳美(R8.2月 57) | J31: 不要 | K31: 4
A32: =ROW()-2 -> 30 | B32: 1 | C32: 4 | D32: =IF(AND(B31=B32,C31=C32),D31+1,1) -> 3 | F32: 櫻井治 | G32: 6－74 | H32: 861－2490 | I32: 治ｵｻﾑR7(76)S24.2.2・美保子ﾐﾎｺ(76)S24.11.4 | J32: 不要 | K32: 3
A33: =ROW()-2 -> 31 | B33: 1 | C33: 4 | D33: =IF(AND(B32=B33,C32=C33),D32+1,1) -> 4 | F33: 松永彰 | G33: 6－74 | H33: 861－2132 | I33: プレミール 彰ｱｷﾗR7(75)、正子(?) | J33: 不要 | K33: 1
A34: =ROW()-2 -> 32 | B34: 1 | C34: 4 | D34: =IF(AND(B33=B34,C33=C34),D33+1,1) -> 5 | F34: 橋本勇 | G34: 6－74 | H34: 861－2905 | I34: 勇ｲｻﾑR7(80)S20.5.18・愛子(79)S21.8.9 | J34: 不要 | K34: 3
A35: =ROW()-2 -> 33 | B35: 1 | C35: 4 | D35: =IF(AND(B34=B35,C34=C35),D34+1,1) -> 6 | F35: 瀧下なつみ | G35: 6－75 | H35: 080-5417-6576 | I35: なつみ(R8.2月 30) R1.4〜スズサンマンション302, 礼 | J35: 不要 | K35: 2
A36: =ROW()-2 -> 34 | B36: 1 | C36: 5 | D36: =IF(AND(B35=B36,C35=C36),D35+1,1) -> 1 | F36: 鈴木洋一 | G36: 6－66－４ G3 | H36: 090-8506-2232 | I36: 102号室 洋一(R8.2月55歳)（861-8656 or 4686）評議員は宣子,理沙,玲奈 | J36: 不要 | K36: 5
A37: =ROW()-2 -> 35 | B37: 1 | C37: 5 | D37: =IF(AND(B36=B37,C36=C37),D36+1,1) -> 2 | E37: ● | F37: 首藤睦 | G37: 6－66－４ G3 | H37: 861－9056 | I37: 203号室 睦(R8.2月56歳) | J37: 不要 | K37: 1
A38: =ROW()-2 -> 36 | B38: 1 | C38: 5 | D38: =IF(AND(B37=B38,C37=C38),D37+1,1) -> 3 | F38: 大野誠治 | G38: 6－66－４ G3 | H38: 861－8652 | I38: 403号室 誠治(R8.2月 61歳), 優李亜 | J38: 不要 | K38: 1
A39: =ROW()-2 -> 37 | B39: 1 | C39: 6 | D39: =IF(AND(B38=B39,C38=C39),D38+1,1) -> 1 | F39: 青山啓二 | G39: 6－66 | H39: 861－3697 | I39: 啓二(R8.2月 73歳), 順子ｼﾞｭﾝｺR7(75) | J39: 不要 | K39: 2
A40: =ROW()-2 -> 38 | B40: 1 | C40: 6 | D40: =IF(AND(B39=B40,C39=C40),D39+1,1) -> 2 | F40: 西田善隆 | G40: 6－70 | H40: 861－6352 | I40: 善隆R8.2月(54) | J40: 不要 | K40: 1
...

Sheet 2026-0426
A1: 駒寄町内会 会員名簿 (2026年04月26日現在) | J1: 避難 支援 | K1: 同居 家族
A2: 通番 | B2: 区 | C2: 班 | D2: No. | E2: 評議員 | F2: 氏名 ／ 屋号 | G2: 住所番地 | H2: 電 話 | I2: 備 考
A3: =ROW()-2 -> 1 | B3: 1 | C3: 1 | D3: =IF(AND(B2=B3,C2=C3),D2+1,1) -> 1 | F3: 中村芳朗 | G3: 6－1 | H3: 861－2770 | I3: 芳朗ﾖｼﾛｳ R8.2月(75) | J3: 要 | K3: 2
A4: =ROW()-2 -> 2 | B4: 1 | C4: 1 | D4: =IF(AND(B3=B4,C3=C4),D3+1,1) -> 2 | F4: 中村治子 | G4: 6－1 | H4: 861－2446 | I4: 治子ﾊﾙｺ R8.2月(81)S19.8.24 | J4: 不要 | K4: 0
A5: =ROW()-2 -> 3 | B5: 1 | C5: 1 | D5: =IF(AND(B4=B5,C4=C5),D4+1,1) -> 3 | F5: 松川正士 | G5: 6－1 | H5: 090-1779-5352 | I5: 正士ﾏｻｼ R8.2月(81)S19.3.31, 真美,妃由 | J5: 不要 | K5: 3 | L5: 861－2384
A6: =ROW()-2 -> 4 | B6: 1 | C6: 1 | D6: =IF(AND(B5=B6,C5=C6),D5+1,1) -> 4 | F6: 和田薪 | G6: 6－1 | H6: 861－2481 | I6: セラヴィ 京子R7(79)S21.7.5 | J6: 不要
A7: =ROW()-2 -> 5 | B7: 1 | C7: 1 | D7: =IF(AND(B6=B7,C6=C7),D6+1,1) -> 5 | F7: 平井進 | G7: 6－2 | H7: 861－3291 | I7: 進 R8.2月(78)S23.2.23 | J7: 不要 | K7: 0
A8: =ROW()-2 -> 6 | B8: 1 | C8: 1 | D8: =IF(AND(B7=B8,C7=C8),D7+1,1) -> 6 | F8: 長谷川聰 | G8: 6－2 | I8: H29.4～ 聰ｻﾄｼ S17.11.16(84) | J8: 不要 | K8: 0
A9: =ROW()-2 -> 7 | B9: 1 | C9: 1 | D9: =IF(AND(B8=B9,C8=C9),D8+1,1) -> 7 | F9: 粟飯原功 | G9: 6－2 | H9: 861－4015 | I9: R7(78)S23.1.19 | J9: 不要 | K9: 0
A10: =ROW()-2 -> 8 | B10: 1 | C10: 1 | D10: =IF(AND(B9=B10,C9=C10),D9+1,1) -> 8 | E10: ● | F10: 高橋正 | G10: 6－2 | H10: 861－0178 | I10: 正(R8.2月 62才)R3.評議員は「しのぶ」さん | J10: 不要 | K10: 2
A11: =ROW()-2 -> 9 | B11: 1 | C11: 1 | D11: =IF(AND(B10=B11,C10=C11),D10+1,1) -> 9 | E11: ◎ | F11: 林信行 | G11: 6－2 | H11: 090-3916-4588 | I11: H29.4(79)～ 046-854-9786 同居佐藤たい子R7(93)S6.11.6 | J11: 要 | K11: 2
A12: =ROW()-2 -> 10 | B12: 1 | C12: 1 | D12: =IF(AND(B11=B12,C11=C12),D11+1,1) -> 10 | F12: 町田恵資 | G12: 6－1 | H12: 046-861-1644 | I12: S44.5.26生 ※行事は不参加
A13: =ROW()-2 -> 11 | B13: 1 | C13: 2 | D13: =IF(AND(B11=B13,C11=C13),D11+1,1) -> 1 | F13: 紺野建設 | G13: 6－69 | H13: 861－3180 | J13: 不要
A14: =ROW()-2 -> 12 | B14: 1 | C14: 2 | D14: =IF(AND(B13=B14,C13=C14),D13+1,1) -> 2 | F14: 遠山悦子 | G14: 6－68 | H14: 861－3815 | I14: 悦子(r8.1月 60) R5.美代子さん逝去 | J14: 不要 | K14: 0
A15: =ROW()-2 -> 13 | B15: 1 | C15: 2 | D15: =IF(AND(B14=B15,C14=C15),D14+1,1) -> 3 | F15: 高瀬一 | G15: 6－69 | H15: 861－0509 | I15: 一ﾊｼﾞﾒR7(77)S23.9.22、幸子(80)S20.7.11、徹(?) | J15: 要 | K15: 6
A16: =ROW()-2 -> 14 | B16: 1 | C16: 2 | D16: =IF(AND(B15=B16,C15=C16),D15+1,1) -> 4 | E16: ◎ | F16: 齋藤勇 | G16: 6－68 | H16: 861－3823 | I16: 勇R8.2月(79)S21.8.4、ヨシ子(93)S6.1.2 | J16: 不要 | K16: 1
A17: =ROW()-2 -> 15 | B17: 1 | C17: 2 | D17: =IF(AND(B16=B17,C16=C17),D16+1,1) -> 5 | F17: 鍋田益男 | G17: 6－68片山303 | H17: 861－5959 | I17: 益男(88)S11.1.24、久枝(86)S14.2.16
A18: =ROW()-2 -> 16 | B18: 1 | C18: 2 | D18: =IF(AND(B17=B18,C17=C18),D17+1,1) -> 6 | F18: マミークリーニング | G18: 6－68 | H18: 861－1220
A19: =ROW()-2 -> 17 | B19: 1 | C19: 2 | D19: =IF(AND(B18=B19,C18=C19),D18+1,1) -> 7 | F19: 佐藤清 | G19: 6－69 | H19: 861－6235 | I19: H29.4～ 佐藤歯科（夜間不在） | J19: 不要 | K19: 0
A20: =ROW()-2 -> 18 | B20: 1 | C20: 2 | D20: =IF(AND(B19=B20,C19=C20),D19+1,1) -> 8 | E20: ● | F20: 戸村則登 | G20: 6－68-19 | H20: 090-6346-9518 | I20: R7.6月加入、S33.7.29生(67) | J20: 不要 | K20: 3
A21: =ROW()-2 -> 19 | B21: 1 | C21: 2 | D21: =IF(AND(B20=B21,C20=C21),D20+1,1) -> 9 | F21: 渡邊秀一 | G21: 6-69-12 | H21: 090-9328-7011 | I21: S62.5.30生(38) | J21: 不要 | K21: 1
A22: =ROW()-2 -> 20 | B22: 1 | C22: 3 | D22: =IF(AND(B19=B22,C19=C22),D19+1,1) -> 1 | E22: ◎ | F22: 佐久間明 | G22: 6－69 | H22: 861－3753 | I22: 明R8.2月(75)、満貴子ﾏｷｺ(?),均(090-9305-5987)梢(080-5078-6336),光,匠,楓 | J22: 不要 | K22: 7
A23: =ROW()-2 -> 21 | B23: 1 | C23: 3 | D23: =IF(AND(B22=B23,C22=C23),D22+1,1) -> 2 | F23: 鳥居スミヱ | G23: 6－77 | H23: 861－4993 | I23: 評議員は鳥居知加代 スミヱ(93)S7.5.31 | J23: 要 | K23: 1
A24: =ROW()-2 -> 22 | B24: 1 | C24: 3 | D24: =IF(AND(B23=B24,C23=C24),D23+1,1) -> 3 | F24: 渋江康弘 | G24: 6－77 | H24: 897－7032 | I24: 康弘ﾔｽﾋﾛR8.2月(82)S18.8.18、秀子ﾋﾃﾞｺ(79)S22.1.22 | J24: 不要 | K24: 1
A25: =ROW()-2 -> 23 | B25: 1 | C25: 3 | D25: =IF(AND(B24=B25,C24=C25),D24+1,1) -> 4 | E25: ● | F25: 石岡明憲 | G25: 6－77 | H25: 861－0925 | I25: (r8.1月 59) | J25: 不要 | K25: 1
A26: =ROW()-2 -> 24 | B26: 1 | C26: 3 | D26: =IF(AND(B25=B26,C25=C26),D25+1,1) -> 5 | F26: 中華料理成都 | G26: 6－77 | H26: 861－8060 | I26: 松本秀雄R8.2月(56) | J26: 不要 | K26: 1
A27: =ROW()-2 -> 25 | B27: 1 | C27: 3 | D27: =IF(AND(B26=B27,C26=C27),D26+1,1) -> 6 | F27: 武藤親弘 | G27: 6－76-4 | H27: 861－5829 | I27: 慎一R7(78)S22.4.25 親弘(R8.2月45歳, 090-7225-8149)敏恵,慎太郎,光次郎 | J27: 不要 | K27: 4
A28: =ROW()-2 -> 26 | B28: 1 | C28: 3 | D28: =IF(AND(B27=B28,C27=C28),D27+1,1) -> 7 | F28: 串一 | G28: 6－77 | H28: 861－2733 | I28: 中村太一 店舗 | J28: 不要
A29: =ROW()-2 -> 27 | B29: 1 | C29: 3 | D29: =IF(AND(B28=B29,C28=C29),D28+1,1) -> 8 | F29: AJITO中村みどり | G29: 6－77 | H29: 887－0676 | I29: 中村修一R8.2月(77)S23.10.15 店舗 | J29: 不要 | K29: 2
A30: =ROW()-2 -> 28 | B30: 1 | C30: 4 | D30: =IF(AND(B29=B30,C29=C30),D29+1,1) -> 1 | E30: ● | F30: 澤登武文 | G30: 6－75 | H30: 861－4214 | I30: 武文(R8.2月 56)R4 弘志さん逝去 | J30: 不要 | K30: 2
A31: =ROW()-2 -> 29 | B31: 1 | C31: 4 | D31: =IF(AND(B30=B31,C30=C31),D30+1,1) -> 2 | E31: ◎ | F31: 秋山芳美 | G31: 6－74 | H31: 861－7234 | I31: 芳美(R8.2月 57) | J31: 不要 | K31: 4
A32: =ROW()-2 -> 30 | B32: 1 | C32: 4 | D32: =IF(AND(B31=B32,C31=C32),D31+1,1) -> 3 | F32: 櫻井治 | G32: 6－74 | H32: 861－2490 | I32: 治ｵｻﾑR7(76)S24.2.2・美保子ﾐﾎｺ(76)S24.11.4 | J32: 不要 | K32: 3
A33: =ROW()-2 -> 31 | B33: 1 | C33: 4 | D33: =IF(AND(B32=B33,C32=C33),D32+1,1) -> 4 | F33: 松永彰 | G33: 6－74 | H33: 861－2132 | I33: プレミール 彰ｱｷﾗR7(75)、正子(?) | J33: 不要 | K33: 1
A34: =ROW()-2 -> 32 | B34: 1 | C34: 4 | D34: =IF(AND(B33=B34,C33=C34),D33+1,1) -> 5 | F34: 橋本勇 | G34: 6－74 | H34: 861－2905 | I34: 勇ｲｻﾑR7(80)S20.5.18・愛子(79)S21.8.9 | J34: 不要 | K34: 3
A35: =ROW()-2 -> 33 | B35: 1 | C35: 4 | D35: =IF(AND(B34=B35,C34=C35),D34+1,1) -> 6 | F35: 瀧下なつみ | G35: 6－75 | H35: 080-5417-6576 | I35: なつみ(R8.2月 30) R1.4〜スズサンマンション302, 礼 | J35: 不要 | K35: 2
A36: =ROW()-2 -> 34 | B36: 1 | C36: 5 | D36: =IF(AND(B35=B36,C35=C36),D35+1,1) -> 1 | E36: ◎ | F36: 鈴木洋一 | G36: 6－66－４ G3 | H36: 090-8506-2232 | I36: 102号室 洋一(R8.2月55歳)（861-8656 or 4686）評議員は宣子,理沙,玲奈 | J36: 不要 | K36: 5
A37: =ROW()-2 -> 35 | B37: 1 | C37: 5 | D37: =IF(AND(B36=B37,C36=C37),D36+1,1) -> 2 | E37: ● | F37: 首藤睦 | G37: 6－66－４ G3 | H37: 861－9056 | I37: 203号室 睦(R8.2月56歳) | J37: 不要 | K37: 1
A38: =ROW()-2 -> 36 | B38: 1 | C38: 5 | D38: =IF(AND(B37=B38,C37=C38),D37+1,1) -> 3 | F38: 大野誠治 | G38: 6－66－４ G3 | H38: 861－8652 | I38: 403号室 誠治(R8.2月 61歳), 優李亜 | J38: 不要 | K38: 1
A39: =ROW()-2 -> 37 | B39: 1 | C39: 6 | D39: =IF(AND(B38=B39,C38=C39),D38+1,1) -> 1 | F39: 青山啓二 | G39: 6－66 | H39: 861－3697 | I39: 啓二(R8.2月 73歳), 順子ｼﾞｭﾝｺR7(75) | J39: 不要 | K39: 2
A40: =ROW()-2 -> 38 | B40: 1 | C40: 6 | D40: =IF(AND(B39=B40,C39=C40),D39+1,1) -> 2 | F40: 西田善隆 | G40: 6－70 | H40: 861－6352 | I40: 善隆R8.2月(54) | J40: 不要 | K40: 1
...

Sheet 2026-0418
A1: 駒寄町内会 会員名簿 (2026年04月18日現在) | J1: 避難 支援 | K1: 同居 家族
A2: 通番 | B2: 区 | C2: 班 | D2: No. | E2: 評議員 | F2: 氏名 ／ 屋号 | G2: 住所番地 | H2: 電 話 | I2: 備 考
A3: =ROW()-2 -> 1 | B3: 1 | C3: 1 | D3: =IF(AND(B2=B3,C2=C3),D2+1,1) -> 1 | F3: 中村芳朗 | G3: 6－1 | H3: 861－2770 | I3: 芳朗ﾖｼﾛｳ R8.2月(75) | J3: 要 | K3: 2
A4: =ROW()-2 -> 2 | B4: 1 | C4: 1 | D4: =IF(AND(B3=B4,C3=C4),D3+1,1) -> 2 | F4: 中村治子 | G4: 6－1 | H4: 861－2446 | I4: 治子ﾊﾙｺ R8.2月(81)S19.8.24 | J4: 不要 | K4: 0
A5: =ROW()-2 -> 3 | B5: 1 | C5: 1 | D5: =IF(AND(B4=B5,C4=C5),D4+1,1) -> 3 | F5: 松川正士 | G5: 6－1 | H5: 861－2384 | I5: 正士ﾏｻｼ R8.2月(81)S19.3.31, 真美,妃由 | J5: 不要 | K5: 3
A6: =ROW()-2 -> 4 | B6: 1 | C6: 1 | D6: =IF(AND(B5=B6,C5=C6),D5+1,1) -> 4 | F6: 和田薪 | G6: 6－1 | H6: 861－2481 | I6: セラヴィ 京子R7(79)S21.7.5 | J6: 不要
A7: =ROW()-2 -> 5 | B7: 1 | C7: 1 | D7: =IF(AND(B6=B7,C6=C7),D6+1,1) -> 5 | F7: 平井進 | G7: 6－2 | H7: 861－3291 | I7: 進 R8.2月(78)S23.2.23 | J7: 不要 | K7: 0
A8: =ROW()-2 -> 6 | B8: 1 | C8: 1 | D8: =IF(AND(B7=B8,C7=C8),D7+1,1) -> 6 | F8: 長谷川聰 | G8: 6－2 | I8: H29.4～ 聰ｻﾄｼ S17.11.16(84) | J8: 不要 | K8: 0
A9: =ROW()-2 -> 7 | B9: 1 | C9: 1 | D9: =IF(AND(B8=B9,C8=C9),D8+1,1) -> 7 | F9: 粟飯原功 | G9: 6－2 | H9: 861－4015 | I9: R7(78)S23.1.19 | J9: 不要 | K9: 0
A10: =ROW()-2 -> 8 | B10: 1 | C10: 1 | D10: =IF(AND(B9=B10,C9=C10),D9+1,1) -> 8 | E10: ● | F10: 高橋正 | G10: 6－2 | H10: 861－0178 | I10: 正(R8.2月 62才)R3.評議員は「しのぶ」さん | J10: 不要 | K10: 2
A11: =ROW()-2 -> 9 | B11: 1 | C11: 1 | D11: =IF(AND(B10=B11,C10=C11),D10+1,1) -> 9 | E11: ◎ | F11: 林信行 | G11: 6－2 | H11: 090-3916-4588 | I11: H29.4(79)～ 046-854-9786 同居佐藤たい子R7(93)S6.11.6 | J11: 要 | K11: 2
A12: =ROW()-2 -> 10 | B12: 1 | C12: 1 | D12: =IF(AND(B11=B12,C11=C12),D11+1,1) -> 10 | F12: 町田恵資 | G12: 6－1 | H12: 046-861-1644 | I12: S44.5.26生 ※行事は不参加
A13: =ROW()-2 -> 11 | B13: 1 | C13: 2 | D13: =IF(AND(B11=B13,C11=C13),D11+1,1) -> 1 | F13: 紺野建設 | G13: 6－69 | H13: 861－3180 | J13: 不要
A14: =ROW()-2 -> 12 | B14: 1 | C14: 2 | D14: =IF(AND(B13=B14,C13=C14),D13+1,1) -> 2 | F14: 遠山悦子 | G14: 6－68 | H14: 861－3815 | I14: 悦子(r8.1月 60) R5.美代子さん逝去 | J14: 不要 | K14: 0
A15: =ROW()-2 -> 13 | B15: 1 | C15: 2 | D15: =IF(AND(B14=B15,C14=C15),D14+1,1) -> 3 | F15: 高瀬一 | G15: 6－69 | H15: 861－0509 | I15: 一ﾊｼﾞﾒR7(77)S23.9.22、幸子(80)S20.7.11、徹(?) | J15: 要 | K15: 6
A16: =ROW()-2 -> 14 | B16: 1 | C16: 2 | D16: =IF(AND(B15=B16,C15=C16),D15+1,1) -> 4 | E16: ◎ | F16: 齋藤勇 | G16: 6－68 | H16: 861－3823 | I16: 勇R8.2月(79)S21.8.4、ヨシ子(93)S6.1.2 | J16: 不要 | K16: 1
A17: =ROW()-2 -> 15 | B17: 1 | C17: 2 | D17: =IF(AND(B16=B17,C16=C17),D16+1,1) -> 5 | F17: 鍋田益男 | G17: 6－68片山303 | H17: 861－5959 | I17: 益男(88)S11.1.24、久枝(86)S14.2.16
A18: =ROW()-2 -> 16 | B18: 1 | C18: 2 | D18: =IF(AND(B17=B18,C17=C18),D17+1,1) -> 6 | F18: マミークリーニング | G18: 6－68 | H18: 861－1220
A19: =ROW()-2 -> 17 | B19: 1 | C19: 2 | D19: =IF(AND(B18=B19,C18=C19),D18+1,1) -> 7 | F19: 佐藤清 | G19: 6－69 | H19: 861－6235 | I19: H29.4～ 佐藤歯科（夜間不在） | J19: 不要 | K19: 0
A20: =ROW()-2 -> 18 | B20: 1 | C20: 2 | D20: =IF(AND(B19=B20,C19=C20),D19+1,1) -> 8 | E20: ● | F20: 戸村則登 | G20: 6－68-19 | H20: 090-6346-9518 | I20: R7.6月加入、S33.7.29生(67) | J20: 不要 | K20: 3
A21: =ROW()-2 -> 19 | B21: 1 | C21: 2 | D21: =IF(AND(B20=B21,C20=C21),D20+1,1) -> 9 | F21: 渡邊秀一 | G21: 6-69-12 | H21: 090-9328-7011 | I21: S62.5.30生(38) | J21: 不要 | K21: 1
A22: =ROW()-2 -> 20 | B22: 1 | C22: 3 | D22: =IF(AND(B19=B22,C19=C22),D19+1,1) -> 1 | E22: ◎ | F22: 佐久間明 | G22: 6－69 | H22: 861－3753 | I22: 明R8.2月(75)、満貴子ﾏｷｺ(?),均(090-9305-5987)梢(080-5078-6336),光,匠,楓 | J22: 不要 | K22: 7
A23: =ROW()-2 -> 21 | B23: 1 | C23: 3 | D23: =IF(AND(B22=B23,C22=C23),D22+1,1) -> 2 | F23: 鳥居スミヱ | G23: 6－77 | H23: 861－4993 | I23: 評議員は鳥居知加代 スミヱ(93)S7.5.31 | J23: 要 | K23: 1
A24: =ROW()-2 -> 22 | B24: 1 | C24: 3 | D24: =IF(AND(B23=B24,C23=C24),D23+1,1) -> 3 | F24: 渋江康弘 | G24: 6－77 | H24: 897－7032 | I24: 康弘ﾔｽﾋﾛR8.2月(82)S18.8.18、秀子ﾋﾃﾞｺ(79)S22.1.22 | J24: 不要 | K24: 1
A25: =ROW()-2 -> 23 | B25: 1 | C25: 3 | D25: =IF(AND(B24=B25,C24=C25),D24+1,1) -> 4 | E25: ● | F25: 石岡明憲 | G25: 6－77 | H25: 861－0925 | I25: (r8.1月 59) | J25: 不要 | K25: 1
A26: =ROW()-2 -> 24 | B26: 1 | C26: 3 | D26: =IF(AND(B25=B26,C25=C26),D25+1,1) -> 5 | F26: 中華料理成都 | G26: 6－77 | H26: 861－8060 | I26: 松本秀雄R8.2月(56) | J26: 不要 | K26: 1
A27: =ROW()-2 -> 25 | B27: 1 | C27: 3 | D27: =IF(AND(B26=B27,C26=C27),D26+1,1) -> 6 | F27: 武藤親弘 | G27: 6－76-4 | H27: 861－5829 | I27: 慎一R7(78)S22.4.25 親弘(R8.2月45歳, 090-7225-8149)敏恵,慎太郎,光次郎 | J27: 不要 | K27: 4
A28: =ROW()-2 -> 26 | B28: 1 | C28: 3 | D28: =IF(AND(B27=B28,C27=C28),D27+1,1) -> 7 | F28: 串一 | G28: 6－77 | H28: 861－2733 | I28: 中村太一 店舗 | J28: 不要
A29: =ROW()-2 -> 27 | B29: 1 | C29: 3 | D29: =IF(AND(B28=B29,C28=C29),D28+1,1) -> 8 | F29: AJITO中村みどり | G29: 6－77 | H29: 887－0676 | I29: 中村修一R8.2月(77)S23.10.15 店舗 | J29: 不要 | K29: 2
A30: =ROW()-2 -> 28 | B30: 1 | C30: 4 | D30: =IF(AND(B29=B30,C29=C30),D29+1,1) -> 1 | E30: ● | F30: 澤登武文 | G30: 6－75 | H30: 861－4214 | I30: 武文(R8.2月 56)R4 弘志さん逝去 | J30: 不要 | K30: 2
A31: =ROW()-2 -> 29 | B31: 1 | C31: 4 | D31: =IF(AND(B30=B31,C30=C31),D30+1,1) -> 2 | E31: ◎ | F31: 秋山芳美 | G31: 6－74 | H31: 861－7234 | I31: 芳美(R8.2月 57) | J31: 不要 | K31: 4
A32: =ROW()-2 -> 30 | B32: 1 | C32: 4 | D32: =IF(AND(B31=B32,C31=C32),D31+1,1) -> 3 | F32: 櫻井治 | G32: 6－74 | H32: 861－2490 | I32: 治ｵｻﾑR7(76)S24.2.2・美保子ﾐﾎｺ(76)S24.11.4 | J32: 不要 | K32: 3
A33: =ROW()-2 -> 31 | B33: 1 | C33: 4 | D33: =IF(AND(B32=B33,C32=C33),D32+1,1) -> 4 | F33: 松永彰 | G33: 6－74 | H33: 861－2132 | I33: プレミール 彰ｱｷﾗR7(75)、正子(?) | J33: 不要 | K33: 1
A34: =ROW()-2 -> 32 | B34: 1 | C34: 4 | D34: =IF(AND(B33=B34,C33=C34),D33+1,1) -> 5 | F34: 橋本勇 | G34: 6－74 | H34: 861－2905 | I34: 勇ｲｻﾑR7(80)S20.5.18・愛子(79)S21.8.9 | J34: 不要 | K34: 3
A35: =ROW()-2 -> 33 | B35: 1 | C35: 4 | D35: =IF(AND(B34=B35,C34=C35),D34+1,1) -> 6 | F35: 瀧下なつみ | G35: 6－75 | H35: 080-5417-6576 | I35: なつみ(R8.2月 30) R1.4〜スズサンマンション302, 礼 | J35: 不要 | K35: 2
A36: =ROW()-2 -> 34 | B36: 1 | C36: 5 | D36: =IF(AND(B35=B36,C35=C36),D35+1,1) -> 1 | E36: ◎ | F36: 鈴木洋一 | G36: 6－66－４ G3 | H36: 090-8506-2232 | I36: 102号室 洋一(R8.2月55歳)（861-8656 or 4686）評議員は宣子,理沙,玲奈 | J36: 不要 | K36: 5
A37: =ROW()-2 -> 35 | B37: 1 | C37: 5 | D37: =IF(AND(B36=B37,C36=C37),D36+1,1) -> 2 | E37: ● | F37: 首藤睦 | G37: 6－66－４ G3 | H37: 861－9056 | I37: 203号室 睦(R8.2月56歳) | J37: 不要 | K37: 1
A38: =ROW()-2 -> 36 | B38: 1 | C38: 5 | D38: =IF(AND(B37=B38,C37=C38),D37+1,1) -> 3 | F38: 大野誠治 | G38: 6－66－４ G3 | H38: 861－8652 | I38: 403号室 誠治(R8.2月 61歳), 優李亜 | J38: 不要 | K38: 1
A39: =ROW()-2 -> 37 | B39: 1 | C39: 6 | D39: =IF(AND(B38=B39,C38=C39),D38+1,1) -> 1 | F39: 青山啓二 | G39: 6－66 | H39: 861－3697 | I39: 啓二(R8.2月 73歳), 順子ｼﾞｭﾝｺR7(75) | J39: 不要 | K39: 2
A40: =ROW()-2 -> 38 | B40: 1 | C40: 6 | D40: =IF(AND(B39=B40,C39=C40),D39+1,1) -> 2 | F40: 西田善隆 | G40: 6－70 | H40: 861－6352 | I40: 善隆R8.2月(54) | J40: 不要 | K40: 1
...

Sheet R8要支援者
A1: 駒寄町内会 Ｒ８要支援者名簿 (2026年03月07日現在) | H1: 避難 支援 | I1: 同居 家族
A2: 通番 | B2: 区 | C2: 班 | D2: 氏名 ／ 屋号 | E2: 電 話 | F2: 基本情報 | G2: 備 考 | H2: 支援 | I2: 家族 | J2: 電 話
A3: 1 | B3: 1 | C3: 1 | D3: 中村芳朗 | E3: 861－2770 | F3: 芳朗ﾖｼﾛｳ(75) | H3: 要 | I3: 2 | J3: 861－2770 | K3: 1
A4: =ROW()-2 -> 2 | B4: 1 | C4: 1 | D4: 中村治子 | E4: 861－2446 | F4: 治子ﾊﾙｺ R8.2月(81)S19.8.24 | H4: 不要 | I4: 0 | J4: 861－2446
A5: =ROW()-2 -> 3 | B5: 1 | C5: 1 | D5: 松川正士 | E5: 861－2384 | F5: 正士ﾏｻｼ R8.2月(81)S19.3.31, 真美,妃由 | H5: 不要 | I5: 3 | J5: 861－2384
A6: =ROW()-2 -> 4 | B6: 1 | C6: 1 | D6: 和田薪 | E6: 861－2481 | F6: セラヴィ 京子R7(79)S21.7.5 | H6: 不要 | J6: 861－2481
A7: =ROW()-2 -> 5 | B7: 1 | C7: 1 | D7: 平井進 | E7: 861－3291 | F7: 進 R8.2月(78)S23.2.23 | H7: 不要 | I7: 0 | J7: 861－3291
A8: =ROW()-2 -> 6 | B8: 1 | C8: 1 | D8: 長谷川聰 | F8: H29.4～ 聰ｻﾄｼ S17.11.16(84) | H8: 不要 | I8: 0
A9: =ROW()-2 -> 7 | B9: 1 | C9: 1 | D9: 粟飯原功 | E9: 861－4015 | F9: R7(78)S23.1.19 | H9: 不要 | I9: 0 | J9: 861－4015
A10: =ROW()-2 -> 8 | B10: 1 | C10: 1 | D10: 高橋正 | E10: 861－0178 | F10: 正(R8.2月 62才)R3.評議員は「しのぶ」さん | H10: 不要 | I10: 2 | J10: 861－0178
A11: 2 | B11: 1 | C11: 1 | D11: 林信行 | E11: 090-3916-4588 | F11: 信行(79) 同居:佐藤たい子(94) | H11: 要 | I11: 2 | J11: 090-3916-4588 | K11: 1
A12: =ROW()-2 -> 10 | B12: 1 | C12: 1 | D12: 町田恵資 | E12: 046-861-1644 | F12: S44.5.26生 ※行事は不参加 | J12: 046-861-1644 | K12: 1
A13: =ROW()-2 -> 11 | B13: 1 | C13: 2 | D13: 紺野建設 | E13: 861－3180 | H13: 不要 | J13: 861－3180
A14: =ROW()-2 -> 12 | B14: 1 | C14: 2 | D14: 遠山悦子 | E14: 861－3815 | F14: 悦子(r8.1月 60) R5.美代子さん逝去 | H14: 不要 | I14: 0 | J14: 861－3815
A15: 3 | B15: 1 | C15: 2 | D15: 高瀬一 | E15: 861－0509 | F15: ﾊｼﾞﾒ(77)、幸子(80)、徹(?) | H15: 要 | I15: 6 | J15: 861－0509 | K15: 1
A16: =ROW()-2 -> 14 | B16: 1 | C16: 2 | D16: 齋藤勇 | E16: 861－3823 | F16: 勇R8.2月(79)S21.8.4、ヨシ子(93)S6.1.2 | H16: 不要 | I16: 1 | J16: 861－3823
A17: =ROW()-2 -> 15 | B17: 1 | C17: 2 | D17: 鍋田益男 | E17: 861－5959 | F17: 益男(88)S11.1.24、久枝(86)S14.2.16 | J17: 861－5959 | K17: 1
A18: =ROW()-2 -> 16 | B18: 1 | C18: 2 | D18: マミークリーニング | E18: 861－1220 | J18: 861－1220 | K18: 1
A19: =ROW()-2 -> 17 | B19: 1 | C19: 2 | D19: 佐藤清 | E19: 861－6235 | F19: H29.4～ 佐藤歯科（夜間不在） | H19: 不要 | I19: 0 | J19: 861－6235
A20: =ROW()-2 -> 18 | B20: 1 | C20: 2 | D20: 戸村則登 | E20: 090-6346-9518 | F20: R7.6月加入、S33.7.29生(67) | H20: 不要 | I20: 3 | J20: 090-6346-9518
A21: =ROW()-2 -> 19 | B21: 1 | C21: 2 | D21: 渡邊秀一 | E21: 090-9328-7011 | F21: S62.5.30生(38) | H21: 不要 | I21: 1 | J21: 090-9328-7011
A22: =ROW()-2 -> 20 | B22: 1 | C22: 3 | D22: 佐久間明 | E22: 861－3753 | F22: 明R8.2月(75)、満貴子ﾏｷｺ(?),均(090-9305-5987)梢(080-5078-6336),光,匠,楓 | H22: 不要 | I22: 7 | J22: 861－3753
A23: 4 | B23: 1 | C23: 3 | D23: 鳥居スミヱ | E23: 861－4993 | F23: 評議員は鳥居知加代 スミヱ(93) | H23: 要 | I23: 1 | J23: 861－4993 | K23: 1
A24: =ROW()-2 -> 22 | B24: 1 | C24: 3 | D24: 渋江康弘 | E24: 897－7032 | F24: 康弘ﾔｽﾋﾛR8.2月(82)S18.8.18、秀子ﾋﾃﾞｺ(79)S22.1.22 | H24: 不要 | I24: 1 | J24: 897－7032
A25: =ROW()-2 -> 23 | B25: 1 | C25: 3 | D25: 石岡明憲 | E25: 861－0925 | F25: (r8.1月 59) | H25: 不要 | I25: 1 | J25: 861－0925
A26: =ROW()-2 -> 24 | B26: 1 | C26: 3 | D26: 中華料理成都 | E26: 861－8060 | F26: 松本秀雄R8.2月(56) | H26: 不要 | I26: 1 | J26: 861－8060
A27: =ROW()-2 -> 25 | B27: 1 | C27: 3 | D27: 武藤親弘 | E27: 861－5829 | F27: 慎一R7(78)S22.4.25 親弘(R8.2月45歳, 090-7225-8149)敏恵,慎太郎,光次郎 | H27: 不要 | I27: 4 | J27: 861－5829
A28: =ROW()-2 -> 26 | B28: 1 | C28: 3 | D28: 串一 | E28: 861－2733 | F28: 中村太一 店舗 | H28: 不要 | J28: 861－2733
A29: =ROW()-2 -> 27 | B29: 1 | C29: 3 | D29: AJITO中村みどり | E29: 887－0676 | F29: 中村修一R8.2月(77)S23.10.15 店舗 | H29: 不要 | I29: 2 | J29: 887－0676
A30: =ROW()-2 -> 28 | B30: 1 | C30: 4 | D30: 澤登武文 | E30: 861－4214 | F30: 武文(R8.2月 56)R4 弘志さん逝去 | H30: 不要 | I30: 2 | J30: 861－4214
A31: =ROW()-2 -> 29 | B31: 1 | C31: 4 | D31: 秋山芳美 | E31: 861－7234 | F31: 芳美(R8.2月 57) | H31: 不要 | I31: 4 | J31: 861－7234
A32: =ROW()-2 -> 30 | B32: 1 | C32: 4 | D32: 櫻井治 | E32: 861－2490 | F32: 治ｵｻﾑR7(76)S24.2.2・美保子ﾐﾎｺ(76)S24.11.4 | H32: 不要 | I32: 3 | J32: 861－2490
A33: =ROW()-2 -> 31 | B33: 1 | C33: 4 | D33: 松永彰 | E33: 861－2132 | F33: プレミール 彰ｱｷﾗR7(75)、正子(?) | H33: 不要 | I33: 1 | J33: 861－2132
A34: =ROW()-2 -> 32 | B34: 1 | C34: 4 | D34: 橋本勇 | E34: 861－2905 | F34: 勇ｲｻﾑR7(80)S20.5.18・愛子(79)S21.8.9 | H34: 不要 | I34: 3 | J34: 861－2905
A35: =ROW()-2 -> 33 | B35: 1 | C35: 4 | D35: 瀧下なつみ | E35: 080-5417-6576 | F35: なつみ(R8.2月 30) R1.4〜スズサンマンション302, 礼 | H35: 不要 | I35: 2 | J35: 080-5417-6576
A36: =ROW()-2 -> 34 | B36: 1 | C36: 5 | D36: 鈴木洋一 | E36: 090-8506-2232 | F36: 102号室 洋一(R8.2月55歳)（861-8656 or 4686）評議員は宣子,理沙,玲奈 | H36: 不要 | I36: 5 | J36: 090-8506-2232
A37: =ROW()-2 -> 35 | B37: 1 | C37: 5 | D37: 首藤睦 | E37: 861－9056 | F37: 203号室 睦(R8.2月56歳) | H37: 不要 | I37: 1 | J37: 861－9056
A38: =ROW()-2 -> 36 | B38: 1 | C38: 5 | D38: 大野誠治 | E38: 861－8652 | F38: 403号室 誠治(R8.2月 61歳), 優李亜 | H38: 不要 | I38: 1 | J38: 861－8652
A39: =ROW()-2 -> 37 | B39: 1 | C39: 6 | D39: 青山啓二 | E39: 861－3697 | F39: 啓二(R8.2月 73歳), 順子ｼﾞｭﾝｺR7(75) | H39: 不要 | I39: 2 | J39: 861－3697
A40: =ROW()-2 -> 38 | B40: 1 | C40: 6 | D40: 西田善隆 | E40: 861－6352 | J40: 861－6352 | K40: 1
...

Sheet 2026-0201
A1: 駒寄町内会 会員名簿 (2026年02月01日現在)
A2: 通番 | B2: 区 | C2: 班 | D2: No. | E2: 評議員 | F2: 氏名 ／ 屋号 | G2: 住所番地 | H2: 電 話 | I2: 備 考
A3: =ROW()-2 -> 1 | B3: 1 | C3: 1 | D3: =IF(AND(B2=B3,C2=C3),D2+1,1) -> 1 | F3: 中村芳朗 | G3: 6－1 | H3: 861－2770 | I3: 芳朗ﾖｼﾛｳ R7(75)
A4: =ROW()-2 -> 2 | B4: 1 | C4: 1 | D4: =IF(AND(B3=B4,C3=C4),D3+1,1) -> 2 | F4: 中村治子 | G4: 6－1 | H4: 861－2446 | I4: 治子ﾊﾙｺ R7(81)S19.8.24
A5: =ROW()-2 -> 3 | B5: 1 | C5: 1 | D5: =IF(AND(B4=B5,C4=C5),D4+1,1) -> 3 | F5: 松川正士 | G5: 6－1 | H5: 861－2384 | I5: 正士ﾏｻｼ R7(81)S19.3.31, 真美,妃由
A6: =ROW()-2 -> 4 | B6: 1 | C6: 1 | D6: =IF(AND(B5=B6,C5=C6),D5+1,1) -> 4 | F6: 和田薪 | G6: 6－1 | H6: 861－2481 | I6: セラヴィ 京子R7(79)S21.7.5
A7: =ROW()-2 -> 5 | B7: 1 | C7: 1 | D7: =IF(AND(B6=B7,C6=C7),D6+1,1) -> 5 | F7: 平井進 | G7: 6－2 | H7: 861－3291 | I7: 進 R7(77)S23.2.23
A8: =ROW()-2 -> 6 | B8: 1 | C8: 1 | D8: =IF(AND(B7=B8,C7=C8),D7+1,1) -> 6 | F8: 長谷川聰 | G8: 6－2 | I8: H29.4～ 聰ｻﾄｼ R7(83)S17.11.16
A9: =ROW()-2 -> 7 | B9: 1 | C9: 1 | D9: =IF(AND(B8=B9,C8=C9),D8+1,1) -> 7 | F9: 粟飯原功 | G9: 6－2 | H9: 861－4015 | I9: R7(77)S23.1.19
A10: =ROW()-2 -> 8 | B10: 1 | C10: 1 | D10: =IF(AND(B9=B10,C9=C10),D9+1,1) -> 8 | F10: 高橋正 | G10: 6－2 | H10: 861－0178 | I10: R3.評議員は「しのぶ」さん
A11: =ROW()-2 -> 9 | B11: 1 | C11: 1 | D11: =IF(AND(B10=B11,C10=C11),D10+1,1) -> 9 | E11: ● | F11: 林信行 | G11: 6－2 | H11: 090-3916-4588 | I11: H29.4～ 046-854-9786 同居佐藤たい子R7(93)S6.11.6
A12: =ROW()-2 -> 10 | B12: 1 | C12: 1 | D12: =IF(AND(B11=B12,C11=C12),D11+1,1) -> 10 | F12: 町田恵資 | G12: 6－1 | H12: 046-861-1644 | I12: S44.5.26生 ※行事は不参加
A13: =ROW()-2 -> 11 | B13: 1 | C13: 2 | D13: =IF(AND(B11=B13,C11=C13),D11+1,1) -> 1 | F13: 紺野建設 | G13: 6－69 | H13: 861－3180
A14: =ROW()-2 -> 12 | B14: 1 | C14: 2 | D14: =IF(AND(B13=B14,C13=C14),D13+1,1) -> 2 | F14: 遠山悦子 | G14: 6－68 | H14: 861－3815 | I14: R5.美代子さん逝去
A15: =ROW()-2 -> 13 | B15: 1 | C15: 2 | D15: =IF(AND(B14=B15,C14=C15),D14+1,1) -> 3 | F15: 高瀬一 | G15: 6－69 | H15: 861－0509 | I15: 一ﾊｼﾞﾒR7(76)S23.9.22、幸子(80)S20.7.11、徹(?)
A16: =ROW()-2 -> 14 | B16: 1 | C16: 2 | D16: =IF(AND(B15=B16,C15=C16),D15+1,1) -> 4 | E16: ● | F16: 齋藤勇 | G16: 6－68 | H16: 861－3823 | I16: 勇R7(79)S21.8.4、ヨシ子(93)S6.1.2
A17: =ROW()-2 -> 15 | B17: 1 | C17: 2 | D17: =IF(AND(B16=B17,C16=C17),D16+1,1) -> 5 | F17: 鍋田益男 | G17: 6－68片山303 | H17: 861－5959 | I17: 益男(88)S11.1.24、久枝(86)S14.2.16
A18: =ROW()-2 -> 16 | B18: 1 | C18: 2 | D18: =IF(AND(B17=B18,C17=C18),D17+1,1) -> 6 | F18: マミークリーニング | G18: 6－68 | H18: 861－1220
A19: =ROW()-2 -> 17 | B19: 1 | C19: 2 | D19: =IF(AND(B18=B19,C18=C19),D18+1,1) -> 7 | F19: 佐藤清 | G19: 6－69 | H19: 861－6235 | I19: H29.4～
A20: =ROW()-2 -> 18 | B20: 1 | C20: 2 | D20: =IF(AND(B19=B20,C19=C20),D19+1,1) -> 8 | F20: 戸村則登 | G20: 6－68-19 | H20: 090-6346-9518 | I20: R7.6月加入、S33.7.29生
A21: =ROW()-2 -> 19 | B21: 1 | C21: 2 | D21: =IF(AND(B20=B21,C20=C21),D20+1,1) -> 9 | F21: 渡邊秀一 | G21: 6-69-12 | H21: 090-9328-7011 | I21: S62.5.30生
A22: =ROW()-2 -> 20 | B22: 1 | C22: 3 | D22: =IF(AND(B19=B22,C19=C22),D19+1,1) -> 1 | E22: ● | F22: 佐久間明 | G22: 6－69 | H22: 861－3753 | I22: 明R7(75)、満貴子ﾏｷｺ(?),均(090-9305-5987)梢(080-5078-6336),光,匠,楓
A23: =ROW()-2 -> 21 | B23: 1 | C23: 3 | D23: =IF(AND(B22=B23,C22=C23),D22+1,1) -> 2 | F23: 鳥居スミヱ | G23: 6－77 | H23: 861－4993 | I23: 評議員は鳥居知加代 スミヱ(93)S7.5.31
A24: =ROW()-2 -> 22 | B24: 1 | C24: 3 | D24: =IF(AND(B23=B24,C23=C24),D23+1,1) -> 3 | F24: 渋江康弘 | G24: 6－77 | H24: 897－7032 | I24: 康弘ﾔｽﾋﾛR7(82)S18.8.18、秀子ﾋﾃﾞｺ(78)S22.1.22
A25: =ROW()-2 -> 23 | B25: 1 | C25: 3 | D25: =IF(AND(B24=B25,C24=C25),D24+1,1) -> 4 | F25: 石岡明憲 | G25: 6－77 | H25: 861－0925
A26: =ROW()-2 -> 24 | B26: 1 | C26: 3 | D26: =IF(AND(B25=B26,C25=C26),D25+1,1) -> 5 | F26: 中華料理成都 | G26: 6－77 | H26: 861－8060 | I26: 松本秀雄
A27: =ROW()-2 -> 25 | B27: 1 | C27: 3 | D27: =IF(AND(B26=B27,C26=C27),D26+1,1) -> 6 | F27: 武藤親弘 | G27: 6－76-4 | H27: 861－5829 | I27: 慎一R7(78)S22.4.25 親弘(090-7225-8149)敏恵,慎太郎,光次郎
A28: =ROW()-2 -> 26 | B28: 1 | C28: 3 | D28: =IF(AND(B27=B28,C27=C28),D27+1,1) -> 7 | F28: 串一 | G28: 6－77 | H28: 861－2733 | I28: 中村太一
A29: =ROW()-2 -> 27 | B29: 1 | C29: 3 | D29: =IF(AND(B28=B29,C28=C29),D28+1,1) -> 8 | F29: AJITO中村みどり | G29: 6－77 | H29: 887－0676 | I29: 中村修一R7(77)S23.10.15
A30: =ROW()-2 -> 28 | B30: 1 | C30: 4 | D30: =IF(AND(B29=B30,C29=C30),D29+1,1) -> 1 | F30: 澤登武文 | G30: 6－75 | H30: 861－4214 | I30: R4 弘志さん逝去
A31: =ROW()-2 -> 29 | B31: 1 | C31: 4 | D31: =IF(AND(B30=B31,C30=C31),D30+1,1) -> 2 | E31: ● | F31: 秋山芳美 | G31: 6－74 | H31: 861－7234
A32: =ROW()-2 -> 30 | B32: 1 | C32: 4 | D32: =IF(AND(B31=B32,C31=C32),D31+1,1) -> 3 | F32: 櫻井治 | G32: 6－74 | H32: 861－2490 | I32: 治ｵｻﾑR7(76)S24.2.2・美保子ﾐﾎｺ(76)S24.11.4
A33: =ROW()-2 -> 31 | B33: 1 | C33: 4 | D33: =IF(AND(B32=B33,C32=C33),D32+1,1) -> 4 | F33: 松永彰 | G33: 6－74 | H33: 861－2132 | I33: プレミール 彰ｱｷﾗR7(75)、正子(?)
A34: =ROW()-2 -> 32 | B34: 1 | C34: 4 | D34: =IF(AND(B33=B34,C33=C34),D33+1,1) -> 5 | F34: 橋本勇 | G34: 6－74 | H34: 861－2905 | I34: 勇ｲｻﾑR7(80)S20.5.18・愛子(79)S21.8.9
A35: =ROW()-2 -> 33 | B35: 1 | C35: 4 | D35: =IF(AND(B34=B35,C34=C35),D34+1,1) -> 6 | F35: 瀧下なつみ | G35: 6－75 | H35: 080-5417-6576 | I35: R1.4〜スズサンマンション302, 礼
A36: =ROW()-2 -> 34 | B36: 1 | C36: 5 | D36: =IF(AND(B35=B36,C35=C36),D35+1,1) -> 1 | E36: ● | F36: 鈴木洋一 | G36: 6－66－４ G3 | H36: 090-8506-2232 | I36: 102号室（861-8656 or 4686）評議員は宣子,理沙,玲奈
A37: =ROW()-2 -> 35 | B37: 1 | C37: 5 | D37: =IF(AND(B36=B37,C36=C37),D36+1,1) -> 2 | F37: 首藤睦 | G37: 6－66－４ G3 | H37: 861－9056 | I37: 203号室
A38: =ROW()-2 -> 36 | B38: 1 | C38: 5 | D38: =IF(AND(B37=B38,C37=C38),D37+1,1) -> 3 | F38: 大野誠治 | G38: 6－66－４ G3 | H38: 861－8652 | I38: 403号室 優李亜
A39: =ROW()-2 -> 37 | B39: 1 | C39: 6 | D39: =IF(AND(B38=B39,C38=C39),D38+1,1) -> 1 | F39: 青山啓二 | G39: 6－66 | H39: 861－3697 | I39: 順子ｼﾞｭﾝｺR7(75)
A40: =ROW()-2 -> 38 | B40: 1 | C40: 6 | D40: =IF(AND(B39=B40,C39=C40),D39+1,1) -> 2 | F40: 西田善隆 | G40: 6－70 | H40: 861－6352
...

Sheet 2026-0125
A1: 駒寄町内会 会員名簿 (2026年01月25日現在)
A2: 通番 | B2: 区 | C2: 班 | D2: No. | E2: 評議員 | F2: 氏名 ／ 屋号 | G2: 住所番地 | H2: 電 話 | I2: 備 考
A3: =ROW()-2 -> 1 | B3: 1 | C3: 1 | D3: =IF(AND(B2=B3,C2=C3),D2+1,1) -> 1 | F3: 中村芳朗 | G3: 6－1 | H3: 861－2770 | I3: 芳朗ﾖｼﾛｳ R7(75)
A4: =ROW()-2 -> 2 | B4: 1 | C4: 1 | D4: =IF(AND(B3=B4,C3=C4),D3+1,1) -> 2 | F4: 中村治子 | G4: 6－1 | H4: 861－2446 | I4: 治子ﾊﾙｺ R7(81)S19.8.24
A5: =ROW()-2 -> 3 | B5: 1 | C5: 1 | D5: =IF(AND(B4=B5,C4=C5),D4+1,1) -> 3 | F5: 松川正士 | G5: 6－1 | H5: 861－2384 | I5: 正士ﾏｻｼ R7(81)S19.3.31, 真美,妃由
A6: =ROW()-2 -> 4 | B6: 1 | C6: 1 | D6: =IF(AND(B5=B6,C5=C6),D5+1,1) -> 4 | F6: 和田薪 | G6: 6－1 | H6: 861－2481 | I6: セラヴィ 京子R7(79)S21.7.5
A7: =ROW()-2 -> 5 | B7: 1 | C7: 1 | D7: =IF(AND(B6=B7,C6=C7),D6+1,1) -> 5 | F7: 平井進 | G7: 6－2 | H7: 861－3291 | I7: 進 R7(77)S23.2.23
A8: =ROW()-2 -> 6 | B8: 1 | C8: 1 | D8: =IF(AND(B7=B8,C7=C8),D7+1,1) -> 6 | F8: 長谷川聰 | G8: 6－2 | I8: H29.4～ 聰ｻﾄｼ R7(83)S17.11.16
A9: =ROW()-2 -> 7 | B9: 1 | C9: 1 | D9: =IF(AND(B8=B9,C8=C9),D8+1,1) -> 7 | F9: 粟飯原功 | G9: 6－2 | H9: 861－4015 | I9: R7(77)S23.1.19
A10: =ROW()-2 -> 8 | B10: 1 | C10: 1 | D10: =IF(AND(B9=B10,C9=C10),D9+1,1) -> 8 | F10: 高橋正 | G10: 6－2 | H10: 861－0178 | I10: R3.評議員は「しのぶ」さん
A11: =ROW()-2 -> 9 | B11: 1 | C11: 1 | D11: =IF(AND(B10=B11,C10=C11),D10+1,1) -> 9 | E11: ● | F11: 林信行 | G11: 6－2 | H11: 090-3916-4588 | I11: H29.4～ 046-854-9786 同居佐藤たい子R7(93)S6.11.6
A12: =ROW()-2 -> 10 | B12: 1 | C12: 1 | D12: =IF(AND(B11=B12,C11=C12),D11+1,1) -> 10 | F12: 町田さん
A13: =ROW()-2 -> 11 | B13: 1 | C13: 2 | D13: =IF(AND(B11=B13,C11=C13),D11+1,1) -> 1 | F13: 紺野建設 | G13: 6－69 | H13: 861－3180
A14: =ROW()-2 -> 12 | B14: 1 | C14: 2 | D14: =IF(AND(B13=B14,C13=C14),D13+1,1) -> 2 | F14: 遠山悦子 | G14: 6－68 | H14: 861－3815 | I14: R5.美代子さん逝去
A15: =ROW()-2 -> 13 | B15: 1 | C15: 2 | D15: =IF(AND(B14=B15,C14=C15),D14+1,1) -> 3 | F15: 高瀬一 | G15: 6－69 | H15: 861－0509 | I15: 一ﾊｼﾞﾒR7(76)S23.9.22、幸子(80)S20.7.11、徹(?)
A16: =ROW()-2 -> 14 | B16: 1 | C16: 2 | D16: =IF(AND(B15=B16,C15=C16),D15+1,1) -> 4 | E16: ● | F16: 齋藤勇 | G16: 6－68 | H16: 861－3823 | I16: 勇R7(79)S21.8.4、ヨシ子(93)S6.1.2
A17: =ROW()-2 -> 15 | B17: 1 | C17: 2 | D17: =IF(AND(B16=B17,C16=C17),D16+1,1) -> 5 | F17: 鍋田益男 | G17: 6－68片山303 | H17: 861－5959 | I17: 益男(88)S11.1.24、久枝(86)S14.2.16
A18: =ROW()-2 -> 16 | B18: 1 | C18: 2 | D18: =IF(AND(B17=B18,C17=C18),D17+1,1) -> 6 | F18: マミークリーニング | G18: 6－68 | H18: 861－1220
A19: =ROW()-2 -> 17 | B19: 1 | C19: 2 | D19: =IF(AND(B18=B19,C18=C19),D18+1,1) -> 7 | F19: 佐藤清 | G19: 6－69 | H19: 861－6235 | I19: H29.4～
A20: =ROW()-2 -> 18 | B20: 1 | C20: 2 | D20: =IF(AND(B19=B20,C19=C20),D19+1,1) -> 8 | F20: 戸村則登 | G20: 6－68-19 | H20: 090-6346-9518 | I20: R7.6月加入、S33.7.29生
A21: =ROW()-2 -> 19 | B21: 1 | C21: 2 | D21: =IF(AND(B20=B21,C20=C21),D20+1,1) -> 9 | F21: 渡辺さん
A22: =ROW()-2 -> 20 | B22: 1 | C22: 3 | D22: =IF(AND(B19=B22,C19=C22),D19+1,1) -> 1 | E22: ● | F22: 佐久間明 | G22: 6－69 | H22: 861－3753 | I22: 明R7(75)、満貴子ﾏｷｺ(?),均(090-9305-5987)梢(080-5078-6336),光,匠,楓
A23: =ROW()-2 -> 21 | B23: 1 | C23: 3 | D23: =IF(AND(B22=B23,C22=C23),D22+1,1) -> 2 | F23: 鳥居スミヱ | G23: 6－77 | H23: 861－4993 | I23: 評議員は鳥居知加代 スミヱ(93)S7.5.31
A24: =ROW()-2 -> 22 | B24: 1 | C24: 3 | D24: =IF(AND(B23=B24,C23=C24),D23+1,1) -> 3 | F24: 渋江康弘 | G24: 6－77 | H24: 897－7032 | I24: 康弘ﾔｽﾋﾛR7(82)S18.8.18、秀子ﾋﾃﾞｺ(78)S22.1.22
A25: =ROW()-2 -> 23 | B25: 1 | C25: 3 | D25: =IF(AND(B24=B25,C24=C25),D24+1,1) -> 4 | F25: 石岡明憲 | G25: 6－77 | H25: 861－0925
A26: =ROW()-2 -> 24 | B26: 1 | C26: 3 | D26: =IF(AND(B25=B26,C25=C26),D25+1,1) -> 5 | F26: 中華料理成都 | G26: 6－77 | H26: 861－8060 | I26: 松本秀雄
A27: =ROW()-2 -> 25 | B27: 1 | C27: 3 | D27: =IF(AND(B26=B27,C26=C27),D26+1,1) -> 6 | F27: 武藤親弘 | G27: 6－76-4 | H27: 861－5829 | I27: 慎一R7(78)S22.4.25 親弘(090-7225-8149)敏恵,慎太郎,光次郎
A28: =ROW()-2 -> 26 | B28: 1 | C28: 3 | D28: =IF(AND(B27=B28,C27=C28),D27+1,1) -> 7 | F28: 串一 | G28: 6－77 | H28: 861－2733 | I28: 中村太一
A29: =ROW()-2 -> 27 | B29: 1 | C29: 3 | D29: =IF(AND(B28=B29,C28=C29),D28+1,1) -> 8 | F29: AJITO中村みどり | G29: 6－77 | H29: 887－0676 | I29: 中村修一R7(77)S23.10.15
A30: =ROW()-2 -> 28 | B30: 1 | C30: 4 | D30: =IF(AND(B29=B30,C29=C30),D29+1,1) -> 1 | F30: 澤登武文 | G30: 6－75 | H30: 861－4214 | I30: R4 弘志さん逝去
A31: =ROW()-2 -> 29 | B31: 1 | C31: 4 | D31: =IF(AND(B30=B31,C30=C31),D30+1,1) -> 2 | E31: ● | F31: 秋山芳美 | G31: 6－74 | H31: 861－7234
A32: =ROW()-2 -> 30 | B32: 1 | C32: 4 | D32: =IF(AND(B31=B32,C31=C32),D31+1,1) -> 3 | F32: 櫻井治 | G32: 6－74 | H32: 861－2490 | I32: 治ｵｻﾑR7(76)S24.2.2・美保子ﾐﾎｺ(76)S24.11.4
A33: =ROW()-2 -> 31 | B33: 1 | C33: 4 | D33: =IF(AND(B32=B33,C32=C33),D32+1,1) -> 4 | F33: 松永彰 | G33: 6－74 | H33: 861－2132 | I33: プレミール 彰ｱｷﾗR7(75)、正子(?)
A34: =ROW()-2 -> 32 | B34: 1 | C34: 4 | D34: =IF(AND(B33=B34,C33=C34),D33+1,1) -> 5 | F34: 橋本勇 | G34: 6－74 | H34: 861－2905 | I34: 勇ｲｻﾑR7(80)S20.5.18・愛子(79)S21.8.9
A35: =ROW()-2 -> 33 | B35: 1 | C35: 4 | D35: =IF(AND(B34=B35,C34=C35),D34+1,1) -> 6 | F35: 瀧下なつみ | G35: 6－75 | H35: 080-5417-6576 | I35: R1.4〜スズサンマンション302, 礼
A36: =ROW()-2 -> 34 | B36: 1 | C36: 5 | D36: =IF(AND(B35=B36,C35=C36),D35+1,1) -> 1 | E36: ● | F36: 鈴木洋一 | G36: 6－66－４ G3 | H36: 090-8506-2232 | I36: 102号室（861-8656 or 4686）評議員は宣子,理沙,玲奈
A37: =ROW()-2 -> 35 | B37: 1 | C37: 5 | D37: =IF(AND(B36=B37,C36=C37),D36+1,1) -> 2 | F37: 首藤睦 | G37: 6－66－４ G3 | H37: 861－9056 | I37: 203号室
A38: =ROW()-2 -> 36 | B38: 1 | C38: 5 | D38: =IF(AND(B37=B38,C37=C38),D37+1,1) -> 3 | F38: 大野誠治 | G38: 6－66－４ G3 | H38: 861－8652 | I38: 403号室 優李亜
A39: =ROW()-2 -> 37 | B39: 1 | C39: 6 | D39: =IF(AND(B38=B39,C38=C39),D38+1,1) -> 1 | F39: 青山啓二 | G39: 6－66 | H39: 861－3697 | I39: 順子ｼﾞｭﾝｺR7(75)
A40: =ROW()-2 -> 38 | B40: 1 | C40: 6 | D40: =IF(AND(B39=B40,C39=C40),D39+1,1) -> 2 | F40: 西田善隆 | G40: 6－70 | H40: 861－6352
...

Sheet 2026-0103
A1: 駒寄町内会 会員名簿 (2026年01月03日現在)
A2: 通番 | B2: 区 | C2: 班 | D2: No. | E2: 評議員 | F2: 氏名 ／ 屋号 | G2: 住所番地 | H2: 電 話 | I2: 備 考
A3: =ROW()-2 -> 1 | B3: 1 | C3: 1 | D3: =IF(AND(B2=B3,C2=C3),D2+1,1) -> 1 | F3: 中村芳朗 | G3: 6－1 | H3: 861－2770 | I3: 芳朗ﾖｼﾛｳ R7(75)
A4: =ROW()-2 -> 2 | B4: 1 | C4: 1 | D4: =IF(AND(B3=B4,C3=C4),D3+1,1) -> 2 | F4: 中村治子 | G4: 6－1 | H4: 861－2446 | I4: 治子ﾊﾙｺ R7(81)S19.8.24
A5: =ROW()-2 -> 3 | B5: 1 | C5: 1 | D5: =IF(AND(B4=B5,C4=C5),D4+1,1) -> 3 | F5: 松川正士 | G5: 6－1 | H5: 861－2384 | I5: 正士ﾏｻｼ R7(81)S19.3.31, 真美,妃由
A6: =ROW()-2 -> 4 | B6: 1 | C6: 1 | D6: =IF(AND(B5=B6,C5=C6),D5+1,1) -> 4 | F6: 和田薪 | G6: 6－1 | H6: 861－2481 | I6: セラヴィ 京子R7(79)S21.7.5
A7: =ROW()-2 -> 5 | B7: 1 | C7: 1 | D7: =IF(AND(B6=B7,C6=C7),D6+1,1) -> 5 | F7: 平井進 | G7: 6－2 | H7: 861－3291 | I7: 進 R7(77)S23.2.23
A8: =ROW()-2 -> 6 | B8: 1 | C8: 1 | D8: =IF(AND(B7=B8,C7=C8),D7+1,1) -> 6 | F8: 長谷川聰 | G8: 6－2 | I8: H29.4～ 聰ｻﾄｼ R7(83)S17.11.16
A9: =ROW()-2 -> 7 | B9: 1 | C9: 1 | D9: =IF(AND(B8=B9,C8=C9),D8+1,1) -> 7 | F9: 粟飯原功 | G9: 6－2 | H9: 861－4015 | I9: R7(77)S23.1.19
A10: =ROW()-2 -> 8 | B10: 1 | C10: 1 | D10: =IF(AND(B9=B10,C9=C10),D9+1,1) -> 8 | F10: 高橋正 | G10: 6－2 | H10: 861－0178 | I10: R3.評議員は「しのぶ」さん
A11: =ROW()-2 -> 9 | B11: 1 | C11: 1 | D11: =IF(AND(B10=B11,C10=C11),D10+1,1) -> 9 | E11: ● | F11: 林信行 | G11: 6－2 | H11: 090-3916-4588 | I11: H29.4～ 046-854-9786 同居佐藤たい子R7(93)S6.11.6
A12: =ROW()-2 -> 10 | B12: 1 | C12: 2 | D12: =IF(AND(B11=B12,C11=C12),D11+1,1) -> 1 | F12: 紺野建設 | G12: 6－69 | H12: 861－3180
A13: =ROW()-2 -> 11 | B13: 1 | C13: 2 | D13: =IF(AND(B12=B13,C12=C13),D12+1,1) -> 2 | F13: 遠山悦子 | G13: 6－68 | H13: 861－3815 | I13: R5.美代子さん逝去
A14: =ROW()-2 -> 12 | B14: 1 | C14: 2 | D14: =IF(AND(B13=B14,C13=C14),D13+1,1) -> 3 | F14: 高瀬一 | G14: 6－69 | H14: 861－0509 | I14: 一ﾊｼﾞﾒR7(76)S23.9.22、幸子(80)S20.7.11、徹(?)
A15: =ROW()-2 -> 13 | B15: 1 | C15: 2 | D15: =IF(AND(B14=B15,C14=C15),D14+1,1) -> 4 | E15: ● | F15: 齋藤勇 | G15: 6－68 | H15: 861－3823 | I15: 勇R7(79)S21.8.4、ヨシ子(93)S6.1.2
A16: =ROW()-2 -> 14 | B16: 1 | C16: 2 | D16: =IF(AND(B15=B16,C15=C16),D15+1,1) -> 5 | F16: 鍋田益男 | G16: 6－68片山303 | H16: 861－5959 | I16: 益男(88)S11.1.24、久枝(86)S14.2.16
A17: =ROW()-2 -> 15 | B17: 1 | C17: 2 | D17: =IF(AND(B16=B17,C16=C17),D16+1,1) -> 6 | F17: マミークリーニング | G17: 6－68 | H17: 861－1220
A18: =ROW()-2 -> 16 | B18: 1 | C18: 2 | D18: =IF(AND(B17=B18,C17=C18),D17+1,1) -> 7 | F18: 佐藤清 | G18: 6－69 | H18: 861－6235 | I18: H29.4～
A19: =ROW()-2 -> 17 | B19: 1 | C19: 2 | D19: =IF(AND(B18=B19,C18=C19),D18+1,1) -> 8 | F19: 戸村則登 | G19: 6－68-19 | H19: 090-6346-9518 | I19: R7.6月加入、S33.7.29生
A20: =ROW()-2 -> 18 | B20: 1 | C20: 2 | D20: =IF(AND(B19=B20,C19=C20),D19+1,1) -> 9 | F20: 渡辺さん
A21: =ROW()-2 -> 19 | B21: 1 | C21: 3 | D21: =IF(AND(B18=B21,C18=C21),D18+1,1) -> 1 | E21: ● | F21: 佐久間明 | G21: 6－69 | H21: 861－3753 | I21: 明R7(75)、満貴子ﾏｷｺ(?),均(090-9305-5987)梢(080-5078-6336),光,匠,楓
A22: =ROW()-2 -> 20 | B22: 1 | C22: 3 | D22: =IF(AND(B21=B22,C21=C22),D21+1,1) -> 2 | F22: 鳥居スミヱ | G22: 6－77 | H22: 861－4993 | I22: 評議員は鳥居知加代 スミヱ(93)S7.5.31
A23: =ROW()-2 -> 21 | B23: 1 | C23: 3 | D23: =IF(AND(B22=B23,C22=C23),D22+1,1) -> 3 | F23: 渋江康弘 | G23: 6－77 | H23: 897－7032 | I23: 康弘ﾔｽﾋﾛR7(82)S18.8.18、秀子ﾋﾃﾞｺ(78)S22.1.22
A24: =ROW()-2 -> 22 | B24: 1 | C24: 3 | D24: =IF(AND(B23=B24,C23=C24),D23+1,1) -> 4 | F24: 石岡明憲 | G24: 6－77 | H24: 861－0925
A25: =ROW()-2 -> 23 | B25: 1 | C25: 3 | D25: =IF(AND(B24=B25,C24=C25),D24+1,1) -> 5 | F25: 中華料理成都 | G25: 6－77 | H25: 861－8060 | I25: 松本秀雄
A26: =ROW()-2 -> 24 | B26: 1 | C26: 3 | D26: =IF(AND(B25=B26,C25=C26),D25+1,1) -> 6 | F26: 武藤親弘 | G26: 6－76-4 | H26: 861－5829 | I26: 慎一R7(78)S22.4.25 親弘(090-7225-8149)敏恵,慎太郎,光次郎
A27: =ROW()-2 -> 25 | B27: 1 | C27: 3 | D27: =IF(AND(B26=B27,C26=C27),D26+1,1) -> 7 | F27: 串一 | G27: 6－77 | H27: 861－2733 | I27: 中村太一
A28: =ROW()-2 -> 26 | B28: 1 | C28: 3 | D28: =IF(AND(B27=B28,C27=C28),D27+1,1) -> 8 | F28: AJITO中村みどり | G28: 6－77 | H28: 887－0676 | I28: 中村修一R7(77)S23.10.15
A29: =ROW()-2 -> 27 | B29: 1 | C29: 4 | D29: =IF(AND(B28=B29,C28=C29),D28+1,1) -> 1 | F29: 澤登武文 | G29: 6－75 | H29: 861－4214 | I29: R4 弘志さん逝去
A30: =ROW()-2 -> 28 | B30: 1 | C30: 4 | D30: =IF(AND(B29=B30,C29=C30),D29+1,1) -> 2 | E30: ● | F30: 秋山芳美 | G30: 6－74 | H30: 861－7234
A31: =ROW()-2 -> 29 | B31: 1 | C31: 4 | D31: =IF(AND(B30=B31,C30=C31),D30+1,1) -> 3 | F31: 櫻井治 | G31: 6－74 | H31: 861－2490 | I31: 治ｵｻﾑR7(76)S24.2.2・美保子ﾐﾎｺ(76)S24.11.4
A32: =ROW()-2 -> 30 | B32: 1 | C32: 4 | D32: =IF(AND(B31=B32,C31=C32),D31+1,1) -> 4 | F32: 松永彰 | G32: 6－74 | H32: 861－2132 | I32: プレミール 彰ｱｷﾗR7(75)、正子(?)
A33: =ROW()-2 -> 31 | B33: 1 | C33: 4 | D33: =IF(AND(B32=B33,C32=C33),D32+1,1) -> 5 | F33: 橋本勇 | G33: 6－74 | H33: 861－2905 | I33: 勇ｲｻﾑR7(80)S20.5.18・愛子(79)S21.8.9
A34: =ROW()-2 -> 32 | B34: 1 | C34: 4 | D34: =IF(AND(B33=B34,C33=C34),D33+1,1) -> 6 | F34: 瀧下なつみ | G34: 6－75 | H34: 080-5417-6576 | I34: R1.4〜スズサンマンション302, 礼
A35: =ROW()-2 -> 33 | B35: 1 | C35: 5 | D35: =IF(AND(B34=B35,C34=C35),D34+1,1) -> 1 | E35: ● | F35: 鈴木洋一 | G35: 6－66－４ G3 | H35: 090-8506-2232 | I35: 102号室（861-8656 or 4686）評議員は宣子,理沙,玲奈
A36: =ROW()-2 -> 34 | B36: 1 | C36: 5 | D36: =IF(AND(B35=B36,C35=C36),D35+1,1) -> 2 | F36: 首藤睦 | G36: 6－66－４ G3 | H36: 861－9056 | I36: 203号室
A37: =ROW()-2 -> 35 | B37: 1 | C37: 5 | D37: =IF(AND(B36=B37,C36=C37),D36+1,1) -> 3 | F37: 大野誠治 | G37: 6－66－４ G3 | H37: 861－8652 | I37: 403号室 優李亜
A38: =ROW()-2 -> 36 | B38: 1 | C38: 6 | D38: =IF(AND(B37=B38,C37=C38),D37+1,1) -> 1 | F38: 青山啓二 | G38: 6－66 | H38: 861－3697 | I38: 順子ｼﾞｭﾝｺR7(75)
A39: =ROW()-2 -> 37 | B39: 1 | C39: 6 | D39: =IF(AND(B38=B39,C38=C39),D38+1,1) -> 2 | F39: 西田善隆 | G39: 6－70 | H39: 861－6352
A40: =ROW()-2 -> 38 | B40: 1 | C40: 6 | D40: =IF(AND(B39=B40,C39=C40),D39+1,1) -> 3 | F40: 渡戸正志 | G40: 6－70 | H40: 861－8128 | I40: 渡戸正志ﾜﾀﾄﾞﾏｻｼR7(78)S22.7.1、清美(?)
...
